Workbook

Sheet Coaching
A1: Prioriteit | B1: Coaching rijschool | C1: aanvraagsdatum | D1: P-nr | E1: Naam | F1: Voornaam | G1: Volledige naam | H1: OT | I1: Teamcoach | J1: Rooster | K1: Opmerkingen | L1: Bus/Tram | M1: Instructeur | N1: Datum Coaching | O1: Werkpunten 1 | P1: Werkpunten 2 | Q1: Beoordeling rijschool | R1: hercoaching noodzakelijk | S1: ingevoerd in SS | T1: Kolom1
C2: 45334 | D2: 37936 | E2: =VLOOKUP(Tabel2[[#This Row],[P-nr]],'data Chauffeur'!A:F,2,FALSE) -> Detaeye | F2: =VLOOKUP(Tabel2[[#This Row],[P-nr]],'data Chauffeur'!A:F,3,FALSE) -> Alexander | G2: =VLOOKUP(Tabel3[[#This Row],[P-nr]],'data Chauffeur'!A:F,6) -> #N/A | H2: =VLOOKUP(Tabel2[[#This Row],[P-nr]],'data Chauffeur'!A:F,6,FALSE) -> Gent stad | I2: =VLOOKUP(Tabel2[[#This Row],[P-nr]],'data Chauffeur'!A:F,4,FALSE) -> Steven Storm | J2: =VLOOKUP(Tabel2[[#This Row],[P-nr]],'data Chauffeur'!A:F,5,FALSE) -> BN24 | K2: ongevallen + aandacht zwakke weggebruiker
C3: 45434 | D3: 36625 | E3: =VLOOKUP(Tabel2[[#This Row],[P-nr]],'data Chauffeur'!A:F,2,FALSE) -> Carion | F3: =VLOOKUP(Tabel2[[#This Row],[P-nr]],'data Chauffeur'!A:F,3,FALSE) -> Rojet | G3: =VLOOKUP(Tabel3[[#This Row],[P-nr]],'data Chauffeur'!A:F,6) -> Gent stad | H3: =VLOOKUP(Tabel2[[#This Row],[P-nr]],'data Chauffeur'!A:F,6,FALSE) -> Gent stad | I3: =VLOOKUP(Tabel2[[#This Row],[P-nr]],'data Chauffeur'!A:F,4,FALSE) -> Kenneth De Rick | J3: =VLOOKUP(Tabel2[[#This Row],[P-nr]],'data Chauffeur'!A:F,5,FALSE) -> BR15 | K3: eco score
C4: 45506 | D4: 33757 | E4: =VLOOKUP(Tabel2[[#This Row],[P-nr]],'data Chauffeur'!A:F,2,FALSE) -> Vergucht | F4: =VLOOKUP(Tabel2[[#This Row],[P-nr]],'data Chauffeur'!A:F,3,FALSE) -> Hugo | G4: =VLOOKUP(Tabel3[[#This Row],[P-nr]],'data Chauffeur'!A:F,6) -> Gent stad | H4: =VLOOKUP(Tabel2[[#This Row],[P-nr]],'data Chauffeur'!A:F,6,FALSE) -> Gent stad | I4: =VLOOKUP(Tabel2[[#This Row],[P-nr]],'data Chauffeur'!A:F,4,FALSE) -> Steven Storm | J4: =VLOOKUP(Tabel2[[#This Row],[P-nr]],'data Chauffeur'!A:F,5,FALSE) -> BN24 | K4: meer dan 5 ongevallen (6 ongevallen)
A5: ja | B5: ja | C5: 45524 | D5: 36228 | E5: =VLOOKUP(Tabel2[[#This Row],[P-nr]],'data Chauffeur'!A:F,2,FALSE) -> Kilinc | F5: =VLOOKUP(Tabel2[[#This Row],[P-nr]],'data Chauffeur'!A:F,3,FALSE) -> Atilay | G5: =VLOOKUP(Tabel3[[#This Row],[P-nr]],'data Chauffeur'!A:F,6) -> Gent stad | H5: =VLOOKUP(Tabel2[[#This Row],[P-nr]],'data Chauffeur'!A:F,6,FALSE) -> Gent stad | I5: =VLOOKUP(Tabel2[[#This Row],[P-nr]],'data Chauffeur'!A:F,4,FALSE) -> Els Vanhoe | J5: =VLOOKUP(Tabel2[[#This Row],[P-nr]],'data Chauffeur'!A:F,5,FALSE) -> RESF | K5: snelheid/rijstijl | L5: Tram
C6: 45569 | D6: 27607 | E6: =VLOOKUP(Tabel2[[#This Row],[P-nr]],'data Chauffeur'!A:F,2,FALSE) -> Frans | F6: =VLOOKUP(Tabel2[[#This Row],[P-nr]],'data Chauffeur'!A:F,3,FALSE) -> Gabriella | G6: =VLOOKUP(Tabel3[[#This Row],[P-nr]],'data Chauffeur'!A:F,6) -> Gent stad | H6: =VLOOKUP(Tabel2[[#This Row],[P-nr]],'data Chauffeur'!A:F,6,FALSE) -> Gent stad | I6: =VLOOKUP(Tabel2[[#This Row],[P-nr]],'data Chauffeur'!A:F,4,FALSE) -> Kenneth De Rick | J6: =VLOOKUP(Tabel2[[#This Row],[P-nr]],'data Chauffeur'!A:F,5,FALSE) -> TN24
C7: 45593 | D7: 36428 | E7: =VLOOKUP(Tabel2[[#This Row],[P-nr]],'data Chauffeur'!A:F,2,FALSE) -> Abdi Shaiye | F7: =VLOOKUP(Tabel2[[#This Row],[P-nr]],'data Chauffeur'!A:F,3,FALSE) -> Rashid | G7: =VLOOKUP(Tabel3[[#This Row],[P-nr]],'data Chauffeur'!A:F,6) -> Gent stad | H7: =VLOOKUP(Tabel2[[#This Row],[P-nr]],'data Chauffeur'!A:F,6,FALSE) -> Gent stad | I7: =VLOOKUP(Tabel2[[#This Row],[P-nr]],'data Chauffeur'!A:F,4,FALSE) -> Lucie Vande Velde | J7: =VLOOKUP(Tabel2[[#This Row],[P-nr]],'data Chauffeur'!A:F,5,FALSE) -> MN24
C8: 45700 | D8: 10324 | E8: =VLOOKUP(Tabel2[[#This Row],[P-nr]],'data Chauffeur'!A:F,2,FALSE) -> Eggermont | F8: =VLOOKUP(Tabel2[[#This Row],[P-nr]],'data Chauffeur'!A:F,3,FALSE) -> Wim | G8: =VLOOKUP(Tabel3[[#This Row],[P-nr]],'data Chauffeur'!A:F,6) -> Gent stad | H8: =VLOOKUP(Tabel2[[#This Row],[P-nr]],'data Chauffeur'!A:F,6,FALSE) -> Gent stad | I8: =VLOOKUP(Tabel2[[#This Row],[P-nr]],'data Chauffeur'!A:F,4,FALSE) -> Bart Van Der Beken | J8: =VLOOKUP(Tabel2[[#This Row],[P-nr]],'data Chauffeur'!A:F,5,FALSE) -> TL12 | K8: meer dan 5 ongevallen (6 ongevallen)
C9: 45714 | D9: 37794 | E9: =VLOOKUP(Tabel2[[#This Row],[P-nr]],'data Chauffeur'!A:F,2,FALSE) -> Demirkaya | F9: =VLOOKUP(Tabel2[[#This Row],[P-nr]],'data Chauffeur'!A:F,3,FALSE) -> Kâzim | G9: =VLOOKUP(Tabel3[[#This Row],[P-nr]],'data Chauffeur'!A:F,6) -> #N/A | H9: =VLOOKUP(Tabel2[[#This Row],[P-nr]],'data Chauffeur'!A:F,6,FALSE) -> Gent stad | I9: =VLOOKUP(Tabel2[[#This Row],[P-nr]],'data Chauffeur'!A:F,4,FALSE) -> Steven Storm | J9: =VLOOKUP(Tabel2[[#This Row],[P-nr]],'data Chauffeur'!A:F,5,FALSE) -> RESF | K9: bruusk remmen/ snelheid
C10: 45714 | D10: 37662 | E10: =VLOOKUP(Tabel2[[#This Row],[P-nr]],'data Chauffeur'!A:F,2,FALSE) -> Van den Meerssche | F10: =VLOOKUP(Tabel2[[#This Row],[P-nr]],'data Chauffeur'!A:F,3,FALSE) -> Steven | G10: =VLOOKUP(Tabel3[[#This Row],[P-nr]],'data Chauffeur'!A:F,6) -> Gent stad | H10: =VLOOKUP(Tabel2[[#This Row],[P-nr]],'data Chauffeur'!A:F,6,FALSE) -> Gent stad | I10: =VLOOKUP(Tabel2[[#This Row],[P-nr]],'data Chauffeur'!A:F,4,FALSE) -> Bart Van Der Beken | J10: =VLOOKUP(Tabel2[[#This Row],[P-nr]],'data Chauffeur'!A:F,5,FALSE) -> BN24 | K10: ongevallen
C11: 45714 | D11: 37313 | E11: =VLOOKUP(Tabel2[[#This Row],[P-nr]],'data Chauffeur'!A:F,2,FALSE) -> Dedeci | F11: =VLOOKUP(Tabel2[[#This Row],[P-nr]],'data Chauffeur'!A:F,3,FALSE) -> Mecit | G11: =VLOOKUP(Tabel3[[#This Row],[P-nr]],'data Chauffeur'!A:F,6) -> Gent stad | H11: =VLOOKUP(Tabel2[[#This Row],[P-nr]],'data Chauffeur'!A:F,6,FALSE) -> Gent stad | I11: =VLOOKUP(Tabel2[[#This Row],[P-nr]],'data Chauffeur'!A:F,4,FALSE) -> Bart Van Der Beken | J11: =VLOOKUP(Tabel2[[#This Row],[P-nr]],'data Chauffeur'!A:F,5,FALSE) -> B09 | K11: ongevallen (7 op 1 jaar
C12: 45714 | D12: 34328 | E12: =VLOOKUP(Tabel2[[#This Row],[P-nr]],'data Chauffeur'!A:F,2,FALSE) -> Kerremans | F12: =VLOOKUP(Tabel2[[#This Row],[P-nr]],'data Chauffeur'!A:F,3,FALSE) -> Jürgen | G12: =VLOOKUP(Tabel3[[#This Row],[P-nr]],'data Chauffeur'!A:F,6) -> Gent stad | H12: =VLOOKUP(Tabel2[[#This Row],[P-nr]],'data Chauffeur'!A:F,6,FALSE) -> Gent stad | I12: =VLOOKUP(Tabel2[[#This Row],[P-nr]],'data Chauffeur'!A:F,4,FALSE) -> Kenneth De Rick | J12: =VLOOKUP(Tabel2[[#This Row],[P-nr]],'data Chauffeur'!A:F,5,FALSE) -> TN24 | K12: meer dan 5 ongevallen (6 ongevallen)
C13: 45715 | D13: 5718 | E13: =VLOOKUP(Tabel2[[#This Row],[P-nr]],'data Chauffeur'!A:F,2,FALSE) -> Dejonckheere | F13: =VLOOKUP(Tabel2[[#This Row],[P-nr]],'data Chauffeur'!A:F,3,FALSE) -> Inge | G13: =VLOOKUP(Tabel3[[#This Row],[P-nr]],'data Chauffeur'!A:F,6) -> Gent stad | H13: =VLOOKUP(Tabel2[[#This Row],[P-nr]],'data Chauffeur'!A:F,6,FALSE) -> Gent stad | I13: =VLOOKUP(Tabel2[[#This Row],[P-nr]],'data Chauffeur'!A:F,4,FALSE) -> Kenneth De Rick | J13: =VLOOKUP(Tabel2[[#This Row],[P-nr]],'data Chauffeur'!A:F,5,FALSE) -> M15 | K13: geen gebruik vrijloop, veel volle tractie en volle remming, niet aangenaam gevoel | L13: Tram
A14: ja | B14: ja | C14: 45959 | D14: 36543 | E14: =VLOOKUP(Tabel2[[#This Row],[P-nr]],'data Chauffeur'!A:F,2,FALSE) -> Babaian | F14: =VLOOKUP(Tabel2[[#This Row],[P-nr]],'data Chauffeur'!A:F,3,FALSE) -> Sammy | G14: =VLOOKUP(Tabel3[[#This Row],[P-nr]],'data Chauffeur'!A:F,6) -> Gent stad | H14: =VLOOKUP(Tabel2[[#This Row],[P-nr]],'data Chauffeur'!A:F,6,FALSE) -> Gent stad | I14: =VLOOKUP(Tabel2[[#This Row],[P-nr]],'data Chauffeur'!A:F,4,FALSE) -> Lucie Vande Velde | J14: =VLOOKUP(Tabel2[[#This Row],[P-nr]],'data Chauffeur'!A:F,5,FALSE) -> RESF | K14: rijstijl
C15: 45721 | D15: 38931 | E15: =VLOOKUP(Tabel2[[#This Row],[P-nr]],'data Chauffeur'!A:F,2,FALSE) -> Sancak | F15: =VLOOKUP(Tabel2[[#This Row],[P-nr]],'data Chauffeur'!A:F,3,FALSE) -> Eyuphan | G15: =VLOOKUP(Tabel3[[#This Row],[P-nr]],'data Chauffeur'!A:F,6) -> Gent stad | H15: =VLOOKUP(Tabel2[[#This Row],[P-nr]],'data Chauffeur'!A:F,6,FALSE) -> Gent stad | I15: =VLOOKUP(Tabel2[[#This Row],[P-nr]],'data Chauffeur'!A:F,4,FALSE) -> Bart Van Der Beken | J15: =VLOOKUP(Tabel2[[#This Row],[P-nr]],'data Chauffeur'!A:F,5,FALSE) -> RESF | K15: ongevallen
C16: 45721 | D16: 37600 | E16: =VLOOKUP(Tabel2[[#This Row],[P-nr]],'data Chauffeur'!A:F,2,FALSE) -> Smesman | F16: =VLOOKUP(Tabel2[[#This Row],[P-nr]],'data Chauffeur'!A:F,3,FALSE) -> Nico | G16: =VLOOKUP(Tabel3[[#This Row],[P-nr]],'data Chauffeur'!A:F,6) -> Gent stad | H16: =VLOOKUP(Tabel2[[#This Row],[P-nr]],'data Chauffeur'!A:F,6,FALSE) -> Gent stad | I16: =VLOOKUP(Tabel2[[#This Row],[P-nr]],'data Chauffeur'!A:F,4,FALSE) -> Lucie Vande Velde | J16: =VLOOKUP(Tabel2[[#This Row],[P-nr]],'data Chauffeur'!A:F,5,FALSE) -> BN24 | K16: ongevallen
C17: 45721 | D17: 39859 | E17: =VLOOKUP(Tabel2[[#This Row],[P-nr]],'data Chauffeur'!A:F,2,FALSE) -> Costers | F17: =VLOOKUP(Tabel2[[#This Row],[P-nr]],'data Chauffeur'!A:F,3,FALSE) -> Kelly | G17: =VLOOKUP(Tabel3[[#This Row],[P-nr]],'data Chauffeur'!A:F,6) -> #N/A | H17: =VLOOKUP(Tabel2[[#This Row],[P-nr]],'data Chauffeur'!A:F,6,FALSE) -> Gent stad | I17: =VLOOKUP(Tabel2[[#This Row],[P-nr]],'data Chauffeur'!A:F,4,FALSE) -> Bart Van Der Beken | J17: =VLOOKUP(Tabel2[[#This Row],[P-nr]],'data Chauffeur'!A:F,5,FALSE) -> RESF | K17: 6 aanrijdingen in 2024 | L17: Bus
C18: 45721 | D18: 35588 | E18: =VLOOKUP(Tabel2[[#This Row],[P-nr]],'data Chauffeur'!A:F,2,FALSE) -> Smesman | F18: =VLOOKUP(Tabel2[[#This Row],[P-nr]],'data Chauffeur'!A:F,3,FALSE) -> Glenn | G18: =VLOOKUP(Tabel3[[#This Row],[P-nr]],'data Chauffeur'!A:F,6) -> Gent stad | H18: =VLOOKUP(Tabel2[[#This Row],[P-nr]],'data Chauffeur'!A:F,6,FALSE) -> Gent stad | I18: =VLOOKUP(Tabel2[[#This Row],[P-nr]],'data Chauffeur'!A:F,4,FALSE) -> Lucie Vande Velde | J18: =VLOOKUP(Tabel2[[#This Row],[P-nr]],'data Chauffeur'!A:F,5,FALSE) -> B09 | L18: Bus/Tram
C19: 45721 | D19: 28737 | E19: =VLOOKUP(Tabel2[[#This Row],[P-nr]],'data Chauffeur'!A:F,2,FALSE) -> El-Mohamed | F19: =VLOOKUP(Tabel2[[#This Row],[P-nr]],'data Chauffeur'!A:F,3,FALSE) -> Mohamed | G19: =VLOOKUP(Tabel3[[#This Row],[P-nr]],'data Chauffeur'!A:F,6) -> Gent stad | H19: =VLOOKUP(Tabel2[[#This Row],[P-nr]],'data Chauffeur'!A:F,6,FALSE) -> Gent stad | I19: =VLOOKUP(Tabel2[[#This Row],[P-nr]],'data Chauffeur'!A:F,4,FALSE) -> Lucie Vande Velde | J19: =VLOOKUP(Tabel2[[#This Row],[P-nr]],'data Chauffeur'!A:F,5,FALSE) -> ML12 | K19: schadegevallen | L19: Bus/Tram
C20: 45721 | D20: 11866 | E20: =VLOOKUP(Tabel2[[#This Row],[P-nr]],'data Chauffeur'!A:F,2,FALSE) -> Bolle | F20: =VLOOKUP(Tabel2[[#This Row],[P-nr]],'data Chauffeur'!A:F,3,FALSE) -> Pascal | G20: =VLOOKUP(Tabel3[[#This Row],[P-nr]],'data Chauffeur'!A:F,6) -> Gent stad | H20: =VLOOKUP(Tabel2[[#This Row],[P-nr]],'data Chauffeur'!A:F,6,FALSE) -> Gent stad | I20: =VLOOKUP(Tabel2[[#This Row],[P-nr]],'data Chauffeur'!A:F,4,FALSE) -> Lucie Vande Velde | J20: =VLOOKUP(Tabel2[[#This Row],[P-nr]],'data Chauffeur'!A:F,5,FALSE) -> TD12 | L20: Tram
C21: 45729 | D21: 9065 | E21: =VLOOKUP(Tabel2[[#This Row],[P-nr]],'data Chauffeur'!A:F,2,FALSE) -> Dewispelaere | F21: =VLOOKUP(Tabel2[[#This Row],[P-nr]],'data Chauffeur'!A:F,3,FALSE) -> Danny | G21: =VLOOKUP(Tabel3[[#This Row],[P-nr]],'data Chauffeur'!A:F,6) -> Gent stad | H21: =VLOOKUP(Tabel2[[#This Row],[P-nr]],'data Chauffeur'!A:F,6,FALSE) -> Gent stad | I21: =VLOOKUP(Tabel2[[#This Row],[P-nr]],'data Chauffeur'!A:F,4,FALSE) -> Els Vanhoe | J21: =VLOOKUP(Tabel2[[#This Row],[P-nr]],'data Chauffeur'!A:F,5,FALSE) -> TV12 | K21: algemene rijstijl/ klantvriendelijkheid | L21: Tram
C22: 45736 | D22: 39532 | E22: =VLOOKUP(Tabel2[[#This Row],[P-nr]],'data Chauffeur'!A:F,2,FALSE) -> Sahin | F22: =VLOOKUP(Tabel2[[#This Row],[P-nr]],'data Chauffeur'!A:F,3,FALSE) -> Orhan | G22: =VLOOKUP(Tabel3[[#This Row],[P-nr]],'data Chauffeur'!A:F,6) -> Gent stad | H22: =VLOOKUP(Tabel2[[#This Row],[P-nr]],'data Chauffeur'!A:F,6,FALSE) -> Gent stad | I22: =VLOOKUP(Tabel2[[#This Row],[P-nr]],'data Chauffeur'!A:F,4,FALSE) -> Christoff Rotty | J22: =VLOOKUP(Tabel2[[#This Row],[P-nr]],'data Chauffeur'!A:F,5,FALSE) -> RESF | K22: ongevallen
C23: 45736 | D23: 37509 | E23: =VLOOKUP(Tabel2[[#This Row],[P-nr]],'data Chauffeur'!A:F,2,FALSE) -> Abdulkader | F23: =VLOOKUP(Tabel2[[#This Row],[P-nr]],'data Chauffeur'!A:F,3,FALSE) -> Sabah | G23: =VLOOKUP(Tabel3[[#This Row],[P-nr]],'data Chauffeur'!A:F,6) -> Gent stad | H23: =VLOOKUP(Tabel2[[#This Row],[P-nr]],'data Chauffeur'!A:F,6,FALSE) -> Gent stad | I23: =VLOOKUP(Tabel2[[#This Row],[P-nr]],'data Chauffeur'!A:F,4,FALSE) -> Bart Van Der Beken | J23: =VLOOKUP(Tabel2[[#This Row],[P-nr]],'data Chauffeur'!A:F,5,FALSE) -> MN24 | K23: ongevallen
C24: 45994 | D24: 27711 | E24: =VLOOKUP(Tabel2[[#This Row],[P-nr]],'data Chauffeur'!A:F,2,FALSE) -> De Schenkel | F24: =VLOOKUP(Tabel2[[#This Row],[P-nr]],'data Chauffeur'!A:F,3,FALSE) -> David | G24: =VLOOKUP(Tabel3[[#This Row],[P-nr]],'data Chauffeur'!A:F,6) -> Gent stad | H24: =VLOOKUP(Tabel2[[#This Row],[P-nr]],'data Chauffeur'!A:F,6,FALSE) -> Gent stad | I24: =VLOOKUP(Tabel2[[#This Row],[P-nr]],'data Chauffeur'!A:F,4,FALSE) -> Christoff Rotty | J24: =VLOOKUP(Tabel2[[#This Row],[P-nr]],'data Chauffeur'!A:F,5,FALSE) -> TR15 | K24: slechte eco score optrekken/afremmen | L24: Bus/Tram
C25: 45736 | D25: 25487 | E25: =VLOOKUP(Tabel2[[#This Row],[P-nr]],'data Chauffeur'!A:F,2,FALSE) -> Devos | F25: =VLOOKUP(Tabel2[[#This Row],[P-nr]],'data Chauffeur'!A:F,3,FALSE) -> Stefaan | G25: =VLOOKUP(Tabel3[[#This Row],[P-nr]],'data Chauffeur'!A:F,6) -> Gent stad | H25: =VLOOKUP(Tabel2[[#This Row],[P-nr]],'data Chauffeur'!A:F,6,FALSE) -> Gent stad | I25: =VLOOKUP(Tabel2[[#This Row],[P-nr]],'data Chauffeur'!A:F,4,FALSE) -> Steven Storm | J25: =VLOOKUP(Tabel2[[#This Row],[P-nr]],'data Chauffeur'!A:F,5,FALSE) -> TL12 | K25: negatieve klantreactie. Kan opgevraagd worden bij teamcoach | L25: Bus/Tram
C26: 45743 | D26: 32951 | E26: =VLOOKUP(Tabel2[[#This Row],[P-nr]],'data Chauffeur'!A:F,2,FALSE) -> De Bruyne | F26: =VLOOKUP(Tabel2[[#This Row],[P-nr]],'data Chauffeur'!A:F,3,FALSE) -> Sonia | G26: =VLOOKUP(Tabel3[[#This Row],[P-nr]],'data Chauffeur'!A:F,6) -> Gent stad | H26: =VLOOKUP(Tabel2[[#This Row],[P-nr]],'data Chauffeur'!A:F,6,FALSE) -> Gent stad | I26: =VLOOKUP(Tabel2[[#This Row],[P-nr]],'data Chauffeur'!A:F,4,FALSE) -> Lucie Vande Velde | J26: =VLOOKUP(Tabel2[[#This Row],[P-nr]],'data Chauffeur'!A:F,5,FALSE) -> B24 | K26: snelheid
B27: ja | C27: 45744 | D27: 36289 | E27: =VLOOKUP(Tabel2[[#This Row],[P-nr]],'data Chauffeur'!A:F,2,FALSE) -> Van Rentergem | F27: =VLOOKUP(Tabel2[[#This Row],[P-nr]],'data Chauffeur'!A:F,3,FALSE) -> Steve | G27: =VLOOKUP(Tabel3[[#This Row],[P-nr]],'data Chauffeur'!A:F,6) -> Gent stad | H27: =VLOOKUP(Tabel2[[#This Row],[P-nr]],'data Chauffeur'!A:F,6,FALSE) -> Gent stad | I27: =VLOOKUP(Tabel2[[#This Row],[P-nr]],'data Chauffeur'!A:F,4,FALSE) -> Els Vanhoe | J27: =VLOOKUP(Tabel2[[#This Row],[P-nr]],'data Chauffeur'!A:F,5,FALSE) -> MN24 | K27: algemene rijstijl
C28: 45772 | D28: 35645 | E28: =VLOOKUP(Tabel2[[#This Row],[P-nr]],'data Chauffeur'!A:F,2,FALSE) -> Jalili | F28: =VLOOKUP(Tabel2[[#This Row],[P-nr]],'data Chauffeur'!A:F,3,FALSE) -> Yaseeb | G28: =VLOOKUP(Tabel3[[#This Row],[P-nr]],'data Chauffeur'!A:F,6) -> Gent stad | H28: =VLOOKUP(Tabel2[[#This Row],[P-nr]],'data Chauffeur'!A:F,6,FALSE) -> Gent stad | I28: =VLOOKUP(Tabel2[[#This Row],[P-nr]],'data Chauffeur'!A:F,4,FALSE) -> Steven Storm | J28: =VLOOKUP(Tabel2[[#This Row],[P-nr]],'data Chauffeur'!A:F,5,FALSE) -> BN24 | K28: ongevallen
A29: ja | B29: ja | C29: 45792 | D29: 30967 | E29: =VLOOKUP(Tabel2[[#This Row],[P-nr]],'data Chauffeur'!A:F,2,FALSE) -> Taser | F29: =VLOOKUP(Tabel2[[#This Row],[P-nr]],'data Chauffeur'!A:F,3,FALSE) -> Fatih | G29: =VLOOKUP(Tabel3[[#This Row],[P-nr]],'data Chauffeur'!A:F,6) -> Gent stad | H29: =VLOOKUP(Tabel2[[#This Row],[P-nr]],'data Chauffeur'!A:F,6,FALSE) -> Gent stad | I29: =VLOOKUP(Tabel2[[#This Row],[P-nr]],'data Chauffeur'!A:F,4,FALSE) -> Dominique De Clercq | J29: =VLOOKUP(Tabel2[[#This Row],[P-nr]],'data Chauffeur'!A:F,5,FALSE) -> BD12 | K29: ongevallen/ rijstijl | L29: Bus/Tram
A30: ja | C30: 45796 | D30: 19917 | E30: =VLOOKUP(Tabel2[[#This Row],[P-nr]],'data Chauffeur'!A:F,2,FALSE) -> Vandevyvere | F30: =VLOOKUP(Tabel2[[#This Row],[P-nr]],'data Chauffeur'!A:F,3,FALSE) -> Frank | G30: =VLOOKUP(Tabel3[[#This Row],[P-nr]],'data Chauffeur'!A:F,6) -> Gent stad | H30: =VLOOKUP(Tabel2[[#This Row],[P-nr]],'data Chauffeur'!A:F,6,FALSE) -> Gent stad | I30: =VLOOKUP(Tabel2[[#This Row],[P-nr]],'data Chauffeur'!A:F,4,FALSE) -> Bart Van Der Beken | J30: =VLOOKUP(Tabel2[[#This Row],[P-nr]],'data Chauffeur'!A:F,5,FALSE) -> GW09 | K30: hercoaching | L30: Bus
C31: 45813 | D31: 41032 | E31: =VLOOKUP(Tabel2[[#This Row],[P-nr]],'data Chauffeur'!A:F,2,FALSE) -> Rocabado Hinojosa | F31: =VLOOKUP(Tabel2[[#This Row],[P-nr]],'data Chauffeur'!A:F,3,FALSE) -> Lukas | G31: =VLOOKUP(Tabel3[[#This Row],[P-nr]],'data Chauffeur'!A:F,6) -> Gent stad | H31: =VLOOKUP(Tabel2[[#This Row],[P-nr]],'data Chauffeur'!A:F,6,FALSE) -> Gent stad | I31: =VLOOKUP(Tabel2[[#This Row],[P-nr]],'data Chauffeur'!A:F,4,FALSE) -> Els Vanhoe | J31: =VLOOKUP(Tabel2[[#This Row],[P-nr]],'data Chauffeur'!A:F,5,FALSE) -> RESF | K31: ongevallen
C32: 45840 | D32: 38648 | E32: =VLOOKUP(Tabel2[[#This Row],[P-nr]],'data Chauffeur'!A:F,2,FALSE) -> Uckuyulu | F32: =VLOOKUP(Tabel2[[#This Row],[P-nr]],'data Chauffeur'!A:F,3,FALSE) -> Muhammet Emin | G32: =VLOOKUP(Tabel3[[#This Row],[P-nr]],'data Chauffeur'!A:F,6) -> Gent stad | H32: =VLOOKUP(Tabel2[[#This Row],[P-nr]],'data Chauffeur'!A:F,6,FALSE) -> Gent stad | I32: =VLOOKUP(Tabel2[[#This Row],[P-nr]],'data Chauffeur'!A:F,4,FALSE) -> Lucie Vande Velde | J32: =VLOOKUP(Tabel2[[#This Row],[P-nr]],'data Chauffeur'!A:F,5,FALSE) -> RESF | K32: schadegevallen
C33: 45849 | D33: 40362 | E33: =VLOOKUP(Tabel2[[#This Row],[P-nr]],'data Chauffeur'!A:F,2,FALSE) -> Kuru | F33: =VLOOKUP(Tabel2[[#This Row],[P-nr]],'data Chauffeur'!A:F,3,FALSE) -> Cetin | G33: =VLOOKUP(Tabel3[[#This Row],[P-nr]],'data Chauffeur'!A:F,6) -> Gent stad | H33: =VLOOKUP(Tabel2[[#This Row],[P-nr]],'data Chauffeur'!A:F,6,FALSE) -> Gent stad | I33: =VLOOKUP(Tabel2[[#This Row],[P-nr]],'data Chauffeur'!A:F,4,FALSE) -> Kenneth De Rick | J33: =VLOOKUP(Tabel2[[#This Row],[P-nr]],'data Chauffeur'!A:F,5,FALSE) -> BO15 | K33: schadegevallen
C34: 45853 | D34: 35246 | E34: =VLOOKUP(Tabel2[[#This Row],[P-nr]],'data Chauffeur'!A:F,2,FALSE) -> De Meyer | F34: =VLOOKUP(Tabel2[[#This Row],[P-nr]],'data Chauffeur'!A:F,3,FALSE) -> Karel | G34: =VLOOKUP(Tabel3[[#This Row],[P-nr]],'data Chauffeur'!A:F,6) -> Gent stad | H34: =VLOOKUP(Tabel2[[#This Row],[P-nr]],'data Chauffeur'!A:F,6,FALSE) -> Gent stad | I34: =VLOOKUP(Tabel2[[#This Row],[P-nr]],'data Chauffeur'!A:F,4,FALSE) -> Els Vanhoe | J34: =VLOOKUP(Tabel2[[#This Row],[P-nr]],'data Chauffeur'!A:F,5,FALSE) -> BN24 | K34: algemene rijstijl | L34: Bus
C35: 45868 | D35: 12684 | E35: =VLOOKUP(Tabel2[[#This Row],[P-nr]],'data Chauffeur'!A:F,2,FALSE) -> Van Den Bossche | F35: =VLOOKUP(Tabel2[[#This Row],[P-nr]],'data Chauffeur'!A:F,3,FALSE) -> Martine | G35: =VLOOKUP(Tabel3[[#This Row],[P-nr]],'data Chauffeur'!A:F,6) -> Gent stad | H35: Gent Stad | I35: =VLOOKUP(Tabel2[[#This Row],[P-nr]],'data Chauffeur'!A:F,4,FALSE) -> Els Vanhoe | J35: =VLOOKUP(Tabel2[[#This Row],[P-nr]],'data Chauffeur'!A:F,5,FALSE) -> G09 | K35: schadegevallen
C36: 45883 | D36: 39929 | E36: =VLOOKUP(Tabel2[[#This Row],[P-nr]],'data Chauffeur'!A:F,2,FALSE) -> Staneva | F36: =VLOOKUP(Tabel2[[#This Row],[P-nr]],'data Chauffeur'!A:F,3,FALSE) -> Mariyana | G36: =VLOOKUP(Tabel3[[#This Row],[P-nr]],'data Chauffeur'!A:F,6) -> Gent stad | H36: Gent Stad | I36: =VLOOKUP(Tabel2[[#This Row],[P-nr]],'data Chauffeur'!A:F,4,FALSE) -> Christoff Rotty | J36: =VLOOKUP(Tabel2[[#This Row],[P-nr]],'data Chauffeur'!A:F,5,FALSE) -> RESF | K36: schadegevallen
C37: 45898 | D37: 21424 | E37: =VLOOKUP(Tabel2[[#This Row],[P-nr]],'data Chauffeur'!A:F,2,FALSE) -> Verstichel | F37: =VLOOKUP(Tabel2[[#This Row],[P-nr]],'data Chauffeur'!A:F,3,FALSE) -> Jethro | G37: =VLOOKUP(Tabel3[[#This Row],[P-nr]],'data Chauffeur'!A:F,6) -> Gent stad | H37: Gent Stad | I37: =VLOOKUP(Tabel2[[#This Row],[P-nr]],'data Chauffeur'!A:F,4,FALSE) -> Els Dewulf | J37: =VLOOKUP(Tabel2[[#This Row],[P-nr]],'data Chauffeur'!A:F,5,FALSE) -> MV12 | K37: schadegevallen
C38: 45898 | D38: 36627 | E38: =VLOOKUP(Tabel2[[#This Row],[P-nr]],'data Chauffeur'!A:F,2,FALSE) -> Dobbelaere | F38: =VLOOKUP(Tabel2[[#This Row],[P-nr]],'data Chauffeur'!A:F,3,FALSE) -> David | G38: =VLOOKUP(Tabel3[[#This Row],[P-nr]],'data Chauffeur'!A:F,6) -> #N/A | H38: Gent Stad | I38: =VLOOKUP(Tabel2[[#This Row],[P-nr]],'data Chauffeur'!A:F,4,FALSE) -> Els Dewulf | J38: =VLOOKUP(Tabel2[[#This Row],[P-nr]],'data Chauffeur'!A:F,5,FALSE) -> B24 | K38: schadegevallen
C39: 45898 | D39: 38475 | E39: =VLOOKUP(Tabel2[[#This Row],[P-nr]],'data Chauffeur'!A:F,2,FALSE) -> Verschraegen | F39: =VLOOKUP(Tabel2[[#This Row],[P-nr]],'data Chauffeur'!A:F,3,FALSE) -> Katleen | G39: =VLOOKUP(Tabel3[[#This Row],[P-nr]],'data Chauffeur'!A:F,6) -> Gent stad | H39: Gent Stad | I39: =VLOOKUP(Tabel2[[#This Row],[P-nr]],'data Chauffeur'!A:F,4,FALSE) -> Els Dewulf | J39: =VLOOKUP(Tabel2[[#This Row],[P-nr]],'data Chauffeur'!A:F,5,FALSE) -> BR15 | K39: schadegevallen
C40: 45898 | D40: 40856 | E40: =VLOOKUP(Tabel2[[#This Row],[P-nr]],'data Chauffeur'!A:F,2,FALSE) -> Neissi | F40: =VLOOKUP(Tabel2[[#This Row],[P-nr]],'data Chauffeur'!A:F,3,FALSE) -> Sadegh | G40: =VLOOKUP(Tabel3[[#This Row],[P-nr]],'data Chauffeur'!A:F,6) -> Gent stad | H40: Gent Stad | I40: =VLOOKUP(Tabel2[[#This Row],[P-nr]],'data Chauffeur'!A:F,4,FALSE) -> Kenneth De Rick | J40: =VLOOKUP(Tabel2[[#This Row],[P-nr]],'data Chauffeur'!A:F,5,FALSE) -> RESF | K40: schadegevallen
...

Sheet Voltooide coachings
A1: Prioriteit | B1: P-nr | C1: Naam | D1: Voornaam | E1: volledige naam | F1: OT | G1: Teamcoach | H1: Dienstrol | I1: Opmerking | J1: Bus/Tram | K1: Instructeur | L1: Datum coaching | M1: Werkpunten 1 | N1: Werkpunten 2 | O1: Beoordeling coaching | P1: Hercoaching noodzakelijk | Q1: Gesprek | R1: Ingevoerd in SSF
B2: 19810 | C2: =VLOOKUP(Tabel3[[#This Row],[P-nr]],'data Chauffeur'!A:F,2,FALSE) -> Willems | D2: =VLOOKUP(Tabel3[[#This Row],[P-nr]],'data Chauffeur'!A:F,3,FALSE) -> Kristine | E2: =CONCATENATE(Tabel3[[#This Row],[P-nr]]," ",Tabel3[[#This Row],[Naam]]," ",Tabel3[[#This Row],[Voornaam]]) -> 19810 Willems Kristine | F2: =VLOOKUP(Tabel3[[#This Row],[P-nr]],'data Chauffeur'!A:F,6) -> #N/A | G2: =VLOOKUP(Tabel3[[#This Row],[P-nr]],'data Chauffeur'!A:F,4,FALSE) -> Dominique De Clercq | H2: =VLOOKUP(Tabel3[[#This Row],[P-nr]],'data Chauffeur'!A:F,5,FALSE) -> TV12 | I2: schade | J2: tram | K2: 6046 Joel De Maegd | L2: 45700 | O2: zeer goed | P2: nee | R2: X
B3: 39779 | C3: =VLOOKUP(Tabel3[[#This Row],[P-nr]],'data Chauffeur'!A:F,2,FALSE) -> Avci | D3: =VLOOKUP(Tabel3[[#This Row],[P-nr]],'data Chauffeur'!A:F,3,FALSE) -> Muhammet Abdullah | E3: =CONCATENATE(Tabel3[[#This Row],[P-nr]]," ",Tabel3[[#This Row],[Naam]]," ",Tabel3[[#This Row],[Voornaam]]) -> 39779 Avci Muhammet Abdullah | F3: =VLOOKUP(Tabel3[[#This Row],[P-nr]],'data Chauffeur'!A:F,6) -> Gent stad | G3: =VLOOKUP(Tabel3[[#This Row],[P-nr]],'data Chauffeur'!A:F,4,FALSE) -> Bart Van Der Beken | H3: =VLOOKUP(Tabel3[[#This Row],[P-nr]],'data Chauffeur'!A:F,5,FALSE) -> RESF | I3: schade | J3: bus | K3: 20608 Joeri Mestdag | L3: 45715 | M3: wegcode | N3: snelheid | O3: voldoende | P3: nee | R3: X
B4: 36513 | C4: =VLOOKUP(Tabel3[[#This Row],[P-nr]],'data Chauffeur'!A:F,2,FALSE) -> Sogut | D4: =VLOOKUP(Tabel3[[#This Row],[P-nr]],'data Chauffeur'!A:F,3,FALSE) -> Rauf | E4: =CONCATENATE(Tabel3[[#This Row],[P-nr]]," ",Tabel3[[#This Row],[Naam]]," ",Tabel3[[#This Row],[Voornaam]]) -> 36513 Sogut Rauf | F4: =VLOOKUP(Tabel3[[#This Row],[P-nr]],'data Chauffeur'!A:F,6) -> Gent stad | G4: =VLOOKUP(Tabel3[[#This Row],[P-nr]],'data Chauffeur'!A:F,4,FALSE) -> Kenneth De Rick | H4: =VLOOKUP(Tabel3[[#This Row],[P-nr]],'data Chauffeur'!A:F,5,FALSE) -> BN24 | J4: bus | K4: 20608 Joeri Mestdag | L4: 45721 | M4: wegcode | N4: GSM | O4: voldoende | P4: nee | R4: X
B5: 35026 | C5: =VLOOKUP(Tabel3[[#This Row],[P-nr]],'data Chauffeur'!A:F,2,FALSE) -> Momsen | D5: =VLOOKUP(Tabel3[[#This Row],[P-nr]],'data Chauffeur'!A:F,3,FALSE) -> Rory | E5: =CONCATENATE(Tabel3[[#This Row],[P-nr]]," ",Tabel3[[#This Row],[Naam]]," ",Tabel3[[#This Row],[Voornaam]]) -> 35026 Momsen Rory | F5: =VLOOKUP(Tabel3[[#This Row],[P-nr]],'data Chauffeur'!A:F,6) -> Gent stad | G5: =VLOOKUP(Tabel3[[#This Row],[P-nr]],'data Chauffeur'!A:F,4,FALSE) -> Steven Storm | H5: =VLOOKUP(Tabel3[[#This Row],[P-nr]],'data Chauffeur'!A:F,5,FALSE) -> BN24 | I5: schade | J5: bus | K5: 20608 Joeri Mestdag | L5: 45721 | O5: goed | R5: X
B6: 34286 | C6: =VLOOKUP(Tabel3[[#This Row],[P-nr]],'data Chauffeur'!A:F,2,FALSE) -> Ghani | D6: =VLOOKUP(Tabel3[[#This Row],[P-nr]],'data Chauffeur'!A:F,3,FALSE) -> Mozamil | E6: =CONCATENATE(Tabel3[[#This Row],[P-nr]]," ",Tabel3[[#This Row],[Naam]]," ",Tabel3[[#This Row],[Voornaam]]) -> 34286 Ghani Mozamil | F6: =VLOOKUP(Tabel3[[#This Row],[P-nr]],'data Chauffeur'!A:F,6) -> Gent stad | G6: =VLOOKUP(Tabel3[[#This Row],[P-nr]],'data Chauffeur'!A:F,4,FALSE) -> Steven Storm | H6: =VLOOKUP(Tabel3[[#This Row],[P-nr]],'data Chauffeur'!A:F,5,FALSE) -> MN24 | I6: schade | J6: bus | K6: 20608 Joeri Mestdag | L6: 45721 | O6: goed | R6: X
B7: 40266 | C7: =VLOOKUP(Tabel3[[#This Row],[P-nr]],'data Chauffeur'!A:F,2,FALSE) -> Taibi | D7: =VLOOKUP(Tabel3[[#This Row],[P-nr]],'data Chauffeur'!A:F,3,FALSE) -> Yassine | E7: =CONCATENATE(Tabel3[[#This Row],[P-nr]]," ",Tabel3[[#This Row],[Naam]]," ",Tabel3[[#This Row],[Voornaam]]) -> 40266 Taibi Yassine | F7: =VLOOKUP(Tabel3[[#This Row],[P-nr]],'data Chauffeur'!A:F,6) -> Gent stad | G7: =VLOOKUP(Tabel3[[#This Row],[P-nr]],'data Chauffeur'!A:F,4,FALSE) -> Christoff Rotty | H7: =VLOOKUP(Tabel3[[#This Row],[P-nr]],'data Chauffeur'!A:F,5,FALSE) -> BR15 | I7: optrekken, afremmen onconfortabel | J7: bus | K7: 8538 Philippe Vandewalle | L7: 45722 | O7: goed | R7: X
B8: 37543 | C8: =VLOOKUP(Tabel3[[#This Row],[P-nr]],'data Chauffeur'!A:F,2,FALSE) -> Öztürk | D8: =VLOOKUP(Tabel3[[#This Row],[P-nr]],'data Chauffeur'!A:F,3,FALSE) -> Bilgehan | E8: =CONCATENATE(Tabel3[[#This Row],[P-nr]]," ",Tabel3[[#This Row],[Naam]]," ",Tabel3[[#This Row],[Voornaam]]) -> 37543 Öztürk Bilgehan | F8: =VLOOKUP(Tabel3[[#This Row],[P-nr]],'data Chauffeur'!A:F,6) -> Gent stad | G8: =VLOOKUP(Tabel3[[#This Row],[P-nr]],'data Chauffeur'!A:F,4,FALSE) -> Kenneth De Rick | H8: =VLOOKUP(Tabel3[[#This Row],[P-nr]],'data Chauffeur'!A:F,5,FALSE) -> RESF | I8: schade | J8: bus | K8: 8538 Philippe Vandewalle | L8: 45726 | O8: voldoende | P8: nee | R8: X
B9: 19917 | C9: =VLOOKUP(Tabel3[[#This Row],[P-nr]],'data Chauffeur'!A:F,2,FALSE) -> Vandevyvere | D9: =VLOOKUP(Tabel3[[#This Row],[P-nr]],'data Chauffeur'!A:F,3,FALSE) -> Frank | E9: =CONCATENATE(Tabel3[[#This Row],[P-nr]]," ",Tabel3[[#This Row],[Naam]]," ",Tabel3[[#This Row],[Voornaam]]) -> 19917 Vandevyvere Frank | F9: =VLOOKUP(Tabel3[[#This Row],[P-nr]],'data Chauffeur'!A:F,6) -> #N/A | G9: =VLOOKUP(Tabel3[[#This Row],[P-nr]],'data Chauffeur'!A:F,4,FALSE) -> Bart Van Der Beken | H9: =VLOOKUP(Tabel3[[#This Row],[P-nr]],'data Chauffeur'!A:F,5,FALSE) -> GW09 | I9: nav slechte vorige coaching | J9: bus | K9: 8538 Philippe Vandewalle | L9: 45727 | M9: wegcode | O9: onvoldoende | P9: ja
B10: 29821 | C10: =VLOOKUP(Tabel3[[#This Row],[P-nr]],'data Chauffeur'!A:F,2,FALSE) -> Mehman Doust | D10: =VLOOKUP(Tabel3[[#This Row],[P-nr]],'data Chauffeur'!A:F,3,FALSE) -> Farhad | E10: =CONCATENATE(Tabel3[[#This Row],[P-nr]]," ",Tabel3[[#This Row],[Naam]]," ",Tabel3[[#This Row],[Voornaam]]) -> 29821 Mehman Doust Farhad | F10: =VLOOKUP(Tabel3[[#This Row],[P-nr]],'data Chauffeur'!A:F,6) -> Gent stad | G10: =VLOOKUP(Tabel3[[#This Row],[P-nr]],'data Chauffeur'!A:F,4,FALSE) -> Dominique De Clercq | H10: =VLOOKUP(Tabel3[[#This Row],[P-nr]],'data Chauffeur'!A:F,5,FALSE) -> TR15 | I10: schade | J10: tram | K10: 6046 Joel De Maegd | L10: 45728 | O10: zeer goed | P10: nee | R10: X
B11: 39677 | C11: =VLOOKUP(Tabel3[[#This Row],[P-nr]],'data Chauffeur'!A:F,2,FALSE) -> Tacq | D11: =VLOOKUP(Tabel3[[#This Row],[P-nr]],'data Chauffeur'!A:F,3,FALSE) -> Joey | E11: =CONCATENATE(Tabel3[[#This Row],[P-nr]]," ",Tabel3[[#This Row],[Naam]]," ",Tabel3[[#This Row],[Voornaam]]) -> 39677 Tacq Joey | F11: =VLOOKUP(Tabel3[[#This Row],[P-nr]],'data Chauffeur'!A:F,6) -> Gent stad | G11: =VLOOKUP(Tabel3[[#This Row],[P-nr]],'data Chauffeur'!A:F,4,FALSE) -> Kenneth De Rick | H11: =VLOOKUP(Tabel3[[#This Row],[P-nr]],'data Chauffeur'!A:F,5,FALSE) -> RESF | J11: bus | K11: 20608 Joeri Mestdag | L11: 45736 | M11: wegcode | N11: GSM | O11: voldoende | P11: nee | R11: X
B12: 39728 | C12: =VLOOKUP(Tabel3[[#This Row],[P-nr]],'data Chauffeur'!A:F,2,FALSE) -> Nohut | D12: =VLOOKUP(Tabel3[[#This Row],[P-nr]],'data Chauffeur'!A:F,3,FALSE) -> Baki | E12: =CONCATENATE(Tabel3[[#This Row],[P-nr]]," ",Tabel3[[#This Row],[Naam]]," ",Tabel3[[#This Row],[Voornaam]]) -> 39728 Nohut Baki | F12: =VLOOKUP(Tabel3[[#This Row],[P-nr]],'data Chauffeur'!A:F,6) -> Gent stad | G12: =VLOOKUP(Tabel3[[#This Row],[P-nr]],'data Chauffeur'!A:F,4,FALSE) -> Lucie Vande Velde | H12: =VLOOKUP(Tabel3[[#This Row],[P-nr]],'data Chauffeur'!A:F,5,FALSE) -> RESF | J12: bus | K12: 20608 Joeri Mestdag | L12: 45740 | O12: zeer goed | R12: X
B13: 41012 | C13: =VLOOKUP(Tabel3[[#This Row],[P-nr]],'data Chauffeur'!A:F,2,FALSE) -> Natad | D13: =VLOOKUP(Tabel3[[#This Row],[P-nr]],'data Chauffeur'!A:F,3,FALSE) -> Younes | E13: =CONCATENATE(Tabel3[[#This Row],[P-nr]]," ",Tabel3[[#This Row],[Naam]]," ",Tabel3[[#This Row],[Voornaam]]) -> 41012 Natad Younes | F13: =VLOOKUP(Tabel3[[#This Row],[P-nr]],'data Chauffeur'!A:F,6) -> Gent stad | G13: =VLOOKUP(Tabel3[[#This Row],[P-nr]],'data Chauffeur'!A:F,4,FALSE) -> Els Vanhoe | H13: =VLOOKUP(Tabel3[[#This Row],[P-nr]],'data Chauffeur'!A:F,5,FALSE) -> RESF | I13: schade | J13: bus | K13: 20608 Joeri Mestdag | L13: 45740 | O13: zeer goed | P13: nee | R13: X
A14: ja | B14: 28794 | C14: =VLOOKUP(Tabel3[[#This Row],[P-nr]],'data Chauffeur'!A:F,2,FALSE) -> Van Malderghem | D14: =VLOOKUP(Tabel3[[#This Row],[P-nr]],'data Chauffeur'!A:F,3,FALSE) -> Niels | E14: =CONCATENATE(Tabel3[[#This Row],[P-nr]]," ",Tabel3[[#This Row],[Naam]]," ",Tabel3[[#This Row],[Voornaam]]) -> 28794 Van Malderghem Niels | F14: =VLOOKUP(Tabel3[[#This Row],[P-nr]],'data Chauffeur'!A:F,6) -> Gent stad | G14: =VLOOKUP(Tabel3[[#This Row],[P-nr]],'data Chauffeur'!A:F,4,FALSE) -> Lucie Vande Velde | H14: =VLOOKUP(Tabel3[[#This Row],[P-nr]],'data Chauffeur'!A:F,5,FALSE) -> ML12 | I14: rijstijl tram in bochten | J14: tram | K14: Teamcoach | L14: 45742 | O14: zeer goed | P14: nee | R14: X
B15: 31092 | C15: =VLOOKUP(Tabel3[[#This Row],[P-nr]],'data Chauffeur'!A:F,2,FALSE) -> De Jaeger | D15: =VLOOKUP(Tabel3[[#This Row],[P-nr]],'data Chauffeur'!A:F,3,FALSE) -> Kevin | E15: =CONCATENATE(Tabel3[[#This Row],[P-nr]]," ",Tabel3[[#This Row],[Naam]]," ",Tabel3[[#This Row],[Voornaam]]) -> 31092 De Jaeger Kevin | F15: =VLOOKUP(Tabel3[[#This Row],[P-nr]],'data Chauffeur'!A:F,6) -> Gent stad | G15: =VLOOKUP(Tabel3[[#This Row],[P-nr]],'data Chauffeur'!A:F,4,FALSE) -> Lucie Vande Velde | H15: =VLOOKUP(Tabel3[[#This Row],[P-nr]],'data Chauffeur'!A:F,5,FALSE) -> B24 | J15: bus | K15: 20608 Joeri Mestdag | L15: 45743 | M15: wegcode | N15: oortjes | O15: goed | P15: nee | R15: X
B16: 27711 | C16: =VLOOKUP(Tabel3[[#This Row],[P-nr]],'data Chauffeur'!A:F,2,FALSE) -> De Schenkel | D16: =VLOOKUP(Tabel3[[#This Row],[P-nr]],'data Chauffeur'!A:F,3,FALSE) -> David | E16: =CONCATENATE(Tabel3[[#This Row],[P-nr]]," ",Tabel3[[#This Row],[Naam]]," ",Tabel3[[#This Row],[Voornaam]]) -> 27711 De Schenkel David | F16: =VLOOKUP(Tabel3[[#This Row],[P-nr]],'data Chauffeur'!A:F,6) -> Gent stad | G16: =VLOOKUP(Tabel3[[#This Row],[P-nr]],'data Chauffeur'!A:F,4,FALSE) -> Christoff Rotty | H16: =VLOOKUP(Tabel3[[#This Row],[P-nr]],'data Chauffeur'!A:F,5,FALSE) -> TR15 | J16: tram | K16: 22812 Tom De Clercq | L16: 45743 | N16: snelheid | O16: goed | R16: X
B17: 19249 | C17: =VLOOKUP(Tabel3[[#This Row],[P-nr]],'data Chauffeur'!A:F,2,FALSE) -> Odaci | D17: =VLOOKUP(Tabel3[[#This Row],[P-nr]],'data Chauffeur'!A:F,3,FALSE) -> Kadir | E17: =CONCATENATE(Tabel3[[#This Row],[P-nr]]," ",Tabel3[[#This Row],[Naam]]," ",Tabel3[[#This Row],[Voornaam]]) -> 19249 Odaci Kadir | F17: =VLOOKUP(Tabel3[[#This Row],[P-nr]],'data Chauffeur'!A:F,6) -> #N/A | G17: =VLOOKUP(Tabel3[[#This Row],[P-nr]],'data Chauffeur'!A:F,4,FALSE) -> Lucie Vande Velde | H17: =VLOOKUP(Tabel3[[#This Row],[P-nr]],'data Chauffeur'!A:F,5,FALSE) -> MV12 | K17: 20608 Joeri Mestdag | L17: 45743 | M17: wegcode | N17: snelheid | O17: goed | P17: nee | R17: X
B18: 33982 | C18: =VLOOKUP(Tabel3[[#This Row],[P-nr]],'data Chauffeur'!A:F,2,FALSE) -> Hoffelinck | D18: =VLOOKUP(Tabel3[[#This Row],[P-nr]],'data Chauffeur'!A:F,3,FALSE) -> Thomas | E18: =CONCATENATE(Tabel3[[#This Row],[P-nr]]," ",Tabel3[[#This Row],[Naam]]," ",Tabel3[[#This Row],[Voornaam]]) -> 33982 Hoffelinck Thomas | F18: =VLOOKUP(Tabel3[[#This Row],[P-nr]],'data Chauffeur'!A:F,6) -> Gent stad | G18: =VLOOKUP(Tabel3[[#This Row],[P-nr]],'data Chauffeur'!A:F,4,FALSE) -> Els Dewulf | H18: =VLOOKUP(Tabel3[[#This Row],[P-nr]],'data Chauffeur'!A:F,5,FALSE) -> TO15 | J18: tram | K18: 22812 Tom De Clercq | L18: 45743 | M18: achterruit rijden met tram | O18: goed | R18: X
B19: 33982 | C19: =VLOOKUP(Tabel3[[#This Row],[P-nr]],'data Chauffeur'!A:F,2,FALSE) -> Hoffelinck | D19: =VLOOKUP(Tabel3[[#This Row],[P-nr]],'data Chauffeur'!A:F,3,FALSE) -> Thomas | E19: =CONCATENATE(Tabel3[[#This Row],[P-nr]]," ",Tabel3[[#This Row],[Naam]]," ",Tabel3[[#This Row],[Voornaam]]) -> 33982 Hoffelinck Thomas | F19: =VLOOKUP(Tabel3[[#This Row],[P-nr]],'data Chauffeur'!A:F,6) -> Gent stad | G19: =VLOOKUP(Tabel3[[#This Row],[P-nr]],'data Chauffeur'!A:F,4,FALSE) -> Els Dewulf | H19: =VLOOKUP(Tabel3[[#This Row],[P-nr]],'data Chauffeur'!A:F,5,FALSE) -> TO15 | I19: achterruitrijden rabotstraat in eigen bedding | J19: tram | K19: 22812 Tom De Clercq | L19: 45743 | M19: wegcode | N19: achterruit rijden | O19: voldoende | R19: X
B20: 27711 | C20: =VLOOKUP(Tabel3[[#This Row],[P-nr]],'data Chauffeur'!A:F,2,FALSE) -> De Schenkel | D20: =VLOOKUP(Tabel3[[#This Row],[P-nr]],'data Chauffeur'!A:F,3,FALSE) -> David | E20: =CONCATENATE(Tabel3[[#This Row],[P-nr]]," ",Tabel3[[#This Row],[Naam]]," ",Tabel3[[#This Row],[Voornaam]]) -> 27711 De Schenkel David | F20: =VLOOKUP(Tabel3[[#This Row],[P-nr]],'data Chauffeur'!A:F,6) -> Gent stad | G20: =VLOOKUP(Tabel3[[#This Row],[P-nr]],'data Chauffeur'!A:F,4,FALSE) -> Christoff Rotty | H20: =VLOOKUP(Tabel3[[#This Row],[P-nr]],'data Chauffeur'!A:F,5,FALSE) -> TR15 | I20: snelheid wissels en beweegbare brug | J20: tram | K20: 22812 Tom De Clercq | L20: 45743 | M20: wegcode | O20: goed | R20: X
B21: 36626 | C21: =VLOOKUP(Tabel3[[#This Row],[P-nr]],'data Chauffeur'!A:F,2,FALSE) -> Kartal | D21: =VLOOKUP(Tabel3[[#This Row],[P-nr]],'data Chauffeur'!A:F,3,FALSE) -> Kadir | E21: =CONCATENATE(Tabel3[[#This Row],[P-nr]]," ",Tabel3[[#This Row],[Naam]]," ",Tabel3[[#This Row],[Voornaam]]) -> 36626 Kartal Kadir | F21: =VLOOKUP(Tabel3[[#This Row],[P-nr]],'data Chauffeur'!A:F,6) -> Gent stad | G21: =VLOOKUP(Tabel3[[#This Row],[P-nr]],'data Chauffeur'!A:F,4,FALSE) -> Els Dewulf | H21: =VLOOKUP(Tabel3[[#This Row],[P-nr]],'data Chauffeur'!A:F,5,FALSE) -> BR15 | I21: schade | J21: bus | K21: 20608 Joeri Mestdag | L21: 45744 | M21: Klantenzorg | N21: te vroeg rijden | O21: goed | P21: nee | R21: X
B22: 39660 | C22: =VLOOKUP(Tabel3[[#This Row],[P-nr]],'data Chauffeur'!A:F,2,FALSE) -> Lloyd | D22: =VLOOKUP(Tabel3[[#This Row],[P-nr]],'data Chauffeur'!A:F,3,FALSE) -> Glenn | E22: =CONCATENATE(Tabel3[[#This Row],[P-nr]]," ",Tabel3[[#This Row],[Naam]]," ",Tabel3[[#This Row],[Voornaam]]) -> 39660 Lloyd Glenn | F22: =VLOOKUP(Tabel3[[#This Row],[P-nr]],'data Chauffeur'!A:F,6) -> Gent stad | G22: =VLOOKUP(Tabel3[[#This Row],[P-nr]],'data Chauffeur'!A:F,4,FALSE) -> Bart Van Der Beken | H22: =VLOOKUP(Tabel3[[#This Row],[P-nr]],'data Chauffeur'!A:F,5,FALSE) -> RESF | I22: schade | J22: bus | K22: 20608 Joeri Mestdag | L22: 45744 | M22: wegcode | N22: snelheid | O22: goed | P22: nee | R22: X
B23: 38938 | C23: =VLOOKUP(Tabel3[[#This Row],[P-nr]],'data Chauffeur'!A:F,2,FALSE) -> Sedighi | D23: =VLOOKUP(Tabel3[[#This Row],[P-nr]],'data Chauffeur'!A:F,3,FALSE) -> Hamid | E23: =CONCATENATE(Tabel3[[#This Row],[P-nr]]," ",Tabel3[[#This Row],[Naam]]," ",Tabel3[[#This Row],[Voornaam]]) -> 38938 Sedighi Hamid | F23: =VLOOKUP(Tabel3[[#This Row],[P-nr]],'data Chauffeur'!A:F,6) -> Gent stad | G23: =VLOOKUP(Tabel3[[#This Row],[P-nr]],'data Chauffeur'!A:F,4,FALSE) -> Lucie Vande Velde | H23: =VLOOKUP(Tabel3[[#This Row],[P-nr]],'data Chauffeur'!A:F,5,FALSE) -> RESF | J23: bus | K23: 20608 Joeri Mestdag | L23: 45744 | M23: wegcode | N23: snelheid | O23: goed | P23: nee | R23: X
B24: 40645 | C24: =VLOOKUP(Tabel3[[#This Row],[P-nr]],'data Chauffeur'!A:F,2,FALSE) -> Bytebier | D24: =VLOOKUP(Tabel3[[#This Row],[P-nr]],'data Chauffeur'!A:F,3,FALSE) -> Jason | E24: =CONCATENATE(Tabel3[[#This Row],[P-nr]]," ",Tabel3[[#This Row],[Naam]]," ",Tabel3[[#This Row],[Voornaam]]) -> 40645 Bytebier Jason | F24: =VLOOKUP(Tabel3[[#This Row],[P-nr]],'data Chauffeur'!A:F,6) -> Gent stad | G24: =VLOOKUP(Tabel3[[#This Row],[P-nr]],'data Chauffeur'!A:F,4,FALSE) -> Els Dewulf | H24: =VLOOKUP(Tabel3[[#This Row],[P-nr]],'data Chauffeur'!A:F,5,FALSE) -> RESF | J24: bus | K24: 17552 Daisy De Geyter | L24: 45744 | O24: zeer goed | P24: nee | R24: X
B25: 40294 | C25: =VLOOKUP(Tabel3[[#This Row],[P-nr]],'data Chauffeur'!A:F,2,FALSE) -> Khder | D25: =VLOOKUP(Tabel3[[#This Row],[P-nr]],'data Chauffeur'!A:F,3,FALSE) -> Aram | E25: =CONCATENATE(Tabel3[[#This Row],[P-nr]]," ",Tabel3[[#This Row],[Naam]]," ",Tabel3[[#This Row],[Voornaam]]) -> 40294 Khder Aram | F25: =VLOOKUP(Tabel3[[#This Row],[P-nr]],'data Chauffeur'!A:F,6) -> Gent stad | G25: =VLOOKUP(Tabel3[[#This Row],[P-nr]],'data Chauffeur'!A:F,4,FALSE) -> Christoff Rotty | H25: =VLOOKUP(Tabel3[[#This Row],[P-nr]],'data Chauffeur'!A:F,5,FALSE) -> RESF | I25: coaching van 3/3/25 slecht, werkpunten: remtechniek, snelheid, gsm gebruik | J25: bus | K25: 17552 Daisy De Geyter | L25: 45744 | M25: interne reglementering | N25: oortjes | O25: voldoende | P25: ja | R25: X
B26: 28717 | C26: =VLOOKUP(Tabel3[[#This Row],[P-nr]],'data Chauffeur'!A:F,2,FALSE) -> Dejonckheere | D26: =VLOOKUP(Tabel3[[#This Row],[P-nr]],'data Chauffeur'!A:F,3,FALSE) -> Els | E26: =CONCATENATE(Tabel3[[#This Row],[P-nr]]," ",Tabel3[[#This Row],[Naam]]," ",Tabel3[[#This Row],[Voornaam]]) -> 28717 Dejonckheere Els | F26: =VLOOKUP(Tabel3[[#This Row],[P-nr]],'data Chauffeur'!A:F,6) -> Gent stad | G26: =VLOOKUP(Tabel3[[#This Row],[P-nr]],'data Chauffeur'!A:F,4,FALSE) -> Lucie Vande Velde | H26: =VLOOKUP(Tabel3[[#This Row],[P-nr]],'data Chauffeur'!A:F,5,FALSE) -> GW10 | J26: bus | K26: 20608 Joeri Mestdag | L26: 45749 | M26: wegcode | N26: snelheid | O26: goed | P26: nee | R26: X
B27: 33986 | C27: =VLOOKUP(Tabel3[[#This Row],[P-nr]],'data Chauffeur'!A:F,2,FALSE) -> Göktas | D27: =VLOOKUP(Tabel3[[#This Row],[P-nr]],'data Chauffeur'!A:F,3,FALSE) -> Muharrem | E27: =CONCATENATE(Tabel3[[#This Row],[P-nr]]," ",Tabel3[[#This Row],[Naam]]," ",Tabel3[[#This Row],[Voornaam]]) -> 33986 Göktas Muharrem | F27: =VLOOKUP(Tabel3[[#This Row],[P-nr]],'data Chauffeur'!A:F,6) -> Gent stad | G27: =VLOOKUP(Tabel3[[#This Row],[P-nr]],'data Chauffeur'!A:F,4,FALSE) -> Kenneth De Rick | H27: =VLOOKUP(Tabel3[[#This Row],[P-nr]],'data Chauffeur'!A:F,5,FALSE) -> GW10 | I27: scade | J27: bus | K27: 16707 Wim Van Hende | L27: 45749 | M27: wegcode | N27: GSM | O27: voldoende | P27: ja | R27: X
B28: 41091 | C28: =VLOOKUP(Tabel3[[#This Row],[P-nr]],'data Chauffeur'!A:F,2,FALSE) -> Yavas | D28: =VLOOKUP(Tabel3[[#This Row],[P-nr]],'data Chauffeur'!A:F,3,FALSE) -> Talha | E28: =CONCATENATE(Tabel3[[#This Row],[P-nr]]," ",Tabel3[[#This Row],[Naam]]," ",Tabel3[[#This Row],[Voornaam]]) -> 41091 Yavas Talha | F28: =VLOOKUP(Tabel3[[#This Row],[P-nr]],'data Chauffeur'!A:F,6) -> Gent stad | G28: =VLOOKUP(Tabel3[[#This Row],[P-nr]],'data Chauffeur'!A:F,4,FALSE) -> Dominique De Clercq | H28: =VLOOKUP(Tabel3[[#This Row],[P-nr]],'data Chauffeur'!A:F,5,FALSE) -> RESF | I28: algemene rijstijl/ houding | J28: bus | K28: 20608 Joeri Mestdag | L28: 45749 | M28: te vroeg rijden | O28: goed | P28: nee | R28: X
B29: 35450 | C29: =VLOOKUP(Tabel3[[#This Row],[P-nr]],'data Chauffeur'!A:F,2,FALSE) -> Roos | D29: =VLOOKUP(Tabel3[[#This Row],[P-nr]],'data Chauffeur'!A:F,3,FALSE) -> Hugo | E29: =CONCATENATE(Tabel3[[#This Row],[P-nr]]," ",Tabel3[[#This Row],[Naam]]," ",Tabel3[[#This Row],[Voornaam]]) -> 35450 Roos Hugo | F29: =VLOOKUP(Tabel3[[#This Row],[P-nr]],'data Chauffeur'!A:F,6) -> Gent stad | G29: =VLOOKUP(Tabel3[[#This Row],[P-nr]],'data Chauffeur'!A:F,4,FALSE) -> Els Dewulf | H29: =VLOOKUP(Tabel3[[#This Row],[P-nr]],'data Chauffeur'!A:F,5,FALSE) -> BR15 | J29: bus | K29: peter schijvens | L29: 45749 | O29: goed | R29: X
B30: 27153 | C30: =VLOOKUP(Tabel3[[#This Row],[P-nr]],'data Chauffeur'!A:F,2,FALSE) -> Oben | D30: =VLOOKUP(Tabel3[[#This Row],[P-nr]],'data Chauffeur'!A:F,3,FALSE) -> Thibaud | E30: =CONCATENATE(Tabel3[[#This Row],[P-nr]]," ",Tabel3[[#This Row],[Naam]]," ",Tabel3[[#This Row],[Voornaam]]) -> 27153 Oben Thibaud | F30: =VLOOKUP(Tabel3[[#This Row],[P-nr]],'data Chauffeur'!A:F,6) -> Gent stad | G30: =VLOOKUP(Tabel3[[#This Row],[P-nr]],'data Chauffeur'!A:F,4,FALSE) -> Christoff Rotty | H30: =VLOOKUP(Tabel3[[#This Row],[P-nr]],'data Chauffeur'!A:F,5,FALSE) -> GW09 | J30: bus | K30: peter schijvens | L30: 45749 | O30: goed | R30: X
B31: 41348 | C31: =VLOOKUP(Tabel3[[#This Row],[P-nr]],'data Chauffeur'!A:F,2,FALSE) -> Van Huffel | D31: =VLOOKUP(Tabel3[[#This Row],[P-nr]],'data Chauffeur'!A:F,3,FALSE) -> Tim | E31: =CONCATENATE(Tabel3[[#This Row],[P-nr]]," ",Tabel3[[#This Row],[Naam]]," ",Tabel3[[#This Row],[Voornaam]]) -> 41348 Van Huffel Tim | F31: =VLOOKUP(Tabel3[[#This Row],[P-nr]],'data Chauffeur'!A:F,6) -> Gent stad | G31: =VLOOKUP(Tabel3[[#This Row],[P-nr]],'data Chauffeur'!A:F,4,FALSE) -> Christoff Rotty | H31: =VLOOKUP(Tabel3[[#This Row],[P-nr]],'data Chauffeur'!A:F,5,FALSE) -> RESF | I31: snelheid | J31: bus | K31: 4707 Peter Schijvens | L31: 45749 | O31: onvoldoende | P31: ja | Q31: OK | R31: X
B32: 41246 | C32: =VLOOKUP(Tabel3[[#This Row],[P-nr]],'data Chauffeur'!A:F,2,FALSE) -> Van Holsbeeck | D32: =VLOOKUP(Tabel3[[#This Row],[P-nr]],'data Chauffeur'!A:F,3,FALSE) -> Yana | E32: =CONCATENATE(Tabel3[[#This Row],[P-nr]]," ",Tabel3[[#This Row],[Naam]]," ",Tabel3[[#This Row],[Voornaam]]) -> 41246 Van Holsbeeck Yana | F32: =VLOOKUP(Tabel3[[#This Row],[P-nr]],'data Chauffeur'!A:F,6) -> Gent stad | G32: =VLOOKUP(Tabel3[[#This Row],[P-nr]],'data Chauffeur'!A:F,4,FALSE) -> Dominique De Clercq | H32: =VLOOKUP(Tabel3[[#This Row],[P-nr]],'data Chauffeur'!A:F,5,FALSE) -> RESF | I32: algemene rijstijl/ houding | J32: bus | K32: 16707 Wim Van Hende | L32: 45749 | M32: voertuigbeheersing | O32: goed | P32: nee | R32: X
B33: 39581 | C33: =VLOOKUP(Tabel3[[#This Row],[P-nr]],'data Chauffeur'!A:F,2,FALSE) -> Vandenhaute | D33: =VLOOKUP(Tabel3[[#This Row],[P-nr]],'data Chauffeur'!A:F,3,FALSE) -> Linus | E33: =CONCATENATE(Tabel3[[#This Row],[P-nr]]," ",Tabel3[[#This Row],[Naam]]," ",Tabel3[[#This Row],[Voornaam]]) -> 39581 Vandenhaute Linus | F33: =VLOOKUP(Tabel3[[#This Row],[P-nr]],'data Chauffeur'!A:F,6) -> Gent stad | G33: =VLOOKUP(Tabel3[[#This Row],[P-nr]],'data Chauffeur'!A:F,4,FALSE) -> Els Dewulf | H33: =VLOOKUP(Tabel3[[#This Row],[P-nr]],'data Chauffeur'!A:F,5,FALSE) -> BR15 | J33: bus | K33: 4707 Peter Schijvens | L33: 45755 | O33: zeer goed | R33: X
B34: 38580 | C34: =VLOOKUP(Tabel3[[#This Row],[P-nr]],'data Chauffeur'!A:F,2,FALSE) -> Smajla | D34: =VLOOKUP(Tabel3[[#This Row],[P-nr]],'data Chauffeur'!A:F,3,FALSE) -> Samet | E34: =CONCATENATE(Tabel3[[#This Row],[P-nr]]," ",Tabel3[[#This Row],[Naam]]," ",Tabel3[[#This Row],[Voornaam]]) -> 38580 Smajla Samet | F34: =VLOOKUP(Tabel3[[#This Row],[P-nr]],'data Chauffeur'!A:F,6) -> Gent stad | G34: =VLOOKUP(Tabel3[[#This Row],[P-nr]],'data Chauffeur'!A:F,4,FALSE) -> Els Dewulf | H34: =VLOOKUP(Tabel3[[#This Row],[P-nr]],'data Chauffeur'!A:F,5,FALSE) -> RESF | I34: spontane coaching | J34: bus | K34: 20608 Joeri Mestdag | L34: 45762 | O34: goed | P34: nee | R34: X
B35: 39660 | C35: =VLOOKUP(Tabel3[[#This Row],[P-nr]],'data Chauffeur'!A:F,2,FALSE) -> Lloyd | D35: =VLOOKUP(Tabel3[[#This Row],[P-nr]],'data Chauffeur'!A:F,3,FALSE) -> Glenn | E35: =CONCATENATE(Tabel3[[#This Row],[P-nr]]," ",Tabel3[[#This Row],[Naam]]," ",Tabel3[[#This Row],[Voornaam]]) -> 39660 Lloyd Glenn | F35: =VLOOKUP(Tabel3[[#This Row],[P-nr]],'data Chauffeur'!A:F,6) -> Gent stad | G35: =VLOOKUP(Tabel3[[#This Row],[P-nr]],'data Chauffeur'!A:F,4,FALSE) -> Bart Van Der Beken | H35: =VLOOKUP(Tabel3[[#This Row],[P-nr]],'data Chauffeur'!A:F,5,FALSE) -> RESF | I35: snelheid en stuurhouding | J35: bus | K35: 4707 Peter Schijvens | L35: 45763 | M35: wegcode | O35: slecht | P35: ja | R35: X
B36: 40486 | C36: =VLOOKUP(Tabel3[[#This Row],[P-nr]],'data Chauffeur'!A:F,2,FALSE) -> De Souza | D36: =VLOOKUP(Tabel3[[#This Row],[P-nr]],'data Chauffeur'!A:F,3,FALSE) -> Marcos Eduardo | E36: =CONCATENATE(Tabel3[[#This Row],[P-nr]]," ",Tabel3[[#This Row],[Naam]]," ",Tabel3[[#This Row],[Voornaam]]) -> 40486 De Souza Marcos Eduardo | F36: =VLOOKUP(Tabel3[[#This Row],[P-nr]],'data Chauffeur'!A:F,6) -> Gent stad | G36: =VLOOKUP(Tabel3[[#This Row],[P-nr]],'data Chauffeur'!A:F,4,FALSE) -> Christoff Rotty | H36: =VLOOKUP(Tabel3[[#This Row],[P-nr]],'data Chauffeur'!A:F,5,FALSE) -> RESF | J36: bus | K36: 4707 Peter Schijvens | L36: 45763 | O36: zeer goed | P36: nee | R36: X
B37: 39901 | C37: =VLOOKUP(Tabel3[[#This Row],[P-nr]],'data Chauffeur'!A:F,2,FALSE) -> Basha | D37: =VLOOKUP(Tabel3[[#This Row],[P-nr]],'data Chauffeur'!A:F,3,FALSE) -> Izmir | E37: =CONCATENATE(Tabel3[[#This Row],[P-nr]]," ",Tabel3[[#This Row],[Naam]]," ",Tabel3[[#This Row],[Voornaam]]) -> 39901 Basha Izmir | F37: =VLOOKUP(Tabel3[[#This Row],[P-nr]],'data Chauffeur'!A:F,6) -> Gent stad | G37: =VLOOKUP(Tabel3[[#This Row],[P-nr]],'data Chauffeur'!A:F,4,FALSE) -> Christoff Rotty | H37: =VLOOKUP(Tabel3[[#This Row],[P-nr]],'data Chauffeur'!A:F,5,FALSE) -> RESF | K37: 4707 Peter Schijvens | L37: 45763 | O37: goed | P37: nee | R37: X
B38: 11508 | C38: =VLOOKUP(Tabel3[[#This Row],[P-nr]],'data Chauffeur'!A:F,2,FALSE) -> Beeckman | D38: =VLOOKUP(Tabel3[[#This Row],[P-nr]],'data Chauffeur'!A:F,3,FALSE) -> Nico | E38: =CONCATENATE(Tabel3[[#This Row],[P-nr]]," ",Tabel3[[#This Row],[Naam]]," ",Tabel3[[#This Row],[Voornaam]]) -> 11508 Beeckman Nico | F38: =VLOOKUP(Tabel3[[#This Row],[P-nr]],'data Chauffeur'!A:F,6) -> #N/A | G38: =VLOOKUP(Tabel3[[#This Row],[P-nr]],'data Chauffeur'!A:F,4,FALSE) -> Lucie Vande Velde | H38: =VLOOKUP(Tabel3[[#This Row],[P-nr]],'data Chauffeur'!A:F,5,FALSE) -> SW05 | J38: bus | K38: 4707 Peter Schijvens | L38: 45763 | O38: goed | P38: nee | R38: X
B39: 32169 | C39: =VLOOKUP(Tabel3[[#This Row],[P-nr]],'data Chauffeur'!A:F,2,FALSE) -> Kelchtermans | D39: =VLOOKUP(Tabel3[[#This Row],[P-nr]],'data Chauffeur'!A:F,3,FALSE) -> Raf | E39: =CONCATENATE(Tabel3[[#This Row],[P-nr]]," ",Tabel3[[#This Row],[Naam]]," ",Tabel3[[#This Row],[Voornaam]]) -> 32169 Kelchtermans Raf | F39: =VLOOKUP(Tabel3[[#This Row],[P-nr]],'data Chauffeur'!A:F,6) -> Gent stad | G39: =VLOOKUP(Tabel3[[#This Row],[P-nr]],'data Chauffeur'!A:F,4,FALSE) -> Steven Storm | H39: =VLOOKUP(Tabel3[[#This Row],[P-nr]],'data Chauffeur'!A:F,5,FALSE) -> B24 | I39: spontane coaching | J39: bus | K39: 20608 Joeri Mestdag | L39: 45763 | O39: goed | P39: nee | R39: X
B40: 21424 | C40: =VLOOKUP(Tabel3[[#This Row],[P-nr]],'data Chauffeur'!A:F,2,FALSE) -> Verstichel | D40: =VLOOKUP(Tabel3[[#This Row],[P-nr]],'data Chauffeur'!A:F,3,FALSE) -> Jethro | E40: =CONCATENATE(Tabel3[[#This Row],[P-nr]]," ",Tabel3[[#This Row],[Naam]]," ",Tabel3[[#This Row],[Voornaam]]) -> 21424 Verstichel Jethro | F40: =VLOOKUP(Tabel3[[#This Row],[P-nr]],'data Chauffeur'!A:F,6) -> Gent stad | G40: =VLOOKUP(Tabel3[[#This Row],[P-nr]],'data Chauffeur'!A:F,4,FALSE) -> Els Dewulf | H40: =VLOOKUP(Tabel3[[#This Row],[P-nr]],'data Chauffeur'!A:F,5,FALSE) -> MV12 | I40: schade | J40: bus | K40: joeri mestdag | L40: 45764 | O40: zeer goed | P40: nee | R40: X
...

Sheet draaitabel
A2: Aantal van Datum coaching | B2: Kolomlabels
A3: Rijlabels | B3: goed | C3: Formule1 | D3: Formule2 | E3: onvoldoende | F3: slecht | G3: voldoende | H3: zeer goed | I3: Zeer slecht | J3: Eindtotaal
A4: achterruit rijden met tram | B4: 1 | J4: 1
A5: Geen opmerkingen | B5: 12 | H5: 12 | J5: 24
A6: gsm gebruik | B6: 1 | E6: 1 | J6: 2
A7: interne reglementering | B7: 5 | E7: 6 | G7: 8 | H7: 2 | J7: 21
A8: interne reglementering (gsm en oortjes) | G8: 1 | J8: 1
A9: Kijktechniek bij het nemen van halte en wegrijden van halten moet beter. Neemt regelmatig boorduren mee | E9: 1 | J9: 1
A10: Klantenzorg | B10: 3 | E10: 1 | G10: 2 | J10: 6
A11: meer spiegel gebruik | B11: 2 | J11: 2
A12: positie baan | B12: 1 | J12: 1
A13: rem | G13: 1 | J13: 1
A14: snelheden niet gerespecteerd | B14: 5 | E14: 1 | F14: 1 | G14: 2 | J14: 9
A15: te vroeg rijden | B15: 1 | J15: 1
A16: uniform | H16: 1 | J16: 1
A17: voertuigbeheersing | B17: 12 | G17: 8 | H17: 1 | I17: 1 | J17: 22
A18: wegcode | B18: 15 | E18: 7 | F18: 2 | G18: 21 | I18: 1 | J18: 46
A19: (leeg) | B19: 41 | E19: 2 | G19: 22 | H19: 67 | J19: 132
A20: Positieve coaching | B20: 1 | J20: 1
A21: werkpunten 1 | H21: 1 | J21: 1
A22: aandacht voor correct stuurgebruik
A23: aandoen haltes
A24: achterruit rijden
A25: andere weggebruikers
A26: Behulpzaam
A27: beter naleven verkeerslichten
A28: correct uitvoeren van haltering
A29: Defensief rijden
A30: Geen opmerkingen
A31: GSM
A32: interne reglementering
A33: oortjes
... A49: wegcode
A50: 45838
A51: (leeg) | H51: 1 | J51: 1
A52: 46014 | G52: 1 | J52: 1
A53: aandacht voor correct stuurgebruik
A54: aandoen haltes
A55: achterruit rijden
A56: andere weggebruikers
...

Sheet Ingeplande per TC
A1: Ingepland | B1: Teamcoach | D1: voltooid | E1: teamcoach
A2: =COUNTIF(Coaching!I1:I9880,Tabel1[[#This Row],[Teamcoach]]) -> 4 | B2: Christoff Rotty | D2: =COUNTIF('Voltooide coachings'!G:G,Tabel1[[#This Row],[Teamcoach]]) -> 46 | E2: =Tabel1[[#This Row],[Teamcoach]] -> Christoff Rotty
A3: =COUNTIF(Coaching!I2:I9881,Tabel1[[#This Row],[Teamcoach]]) -> 14 | B3: Bart Van der Beken | D3: =COUNTIF('Voltooide coachings'!G:G,Tabel1[[#This Row],[Teamcoach]]) -> 34 | E3: =Tabel1[[#This Row],[Teamcoach]] -> Bart Van der Beken
A4: =COUNTIF(Coaching!I2:I9882,Tabel1[[#This Row],[Teamcoach]]) -> 5 | B4: Els Dewulf | D4: =COUNTIF('Voltooide coachings'!G:G,Tabel1[[#This Row],[Teamcoach]]) -> 29 | E4: =Tabel1[[#This Row],[Teamcoach]] -> Els Dewulf
A5: =COUNTIF(Coaching!I2:I9883,Tabel1[[#This Row],[Teamcoach]]) -> 9 | B5: Els Vanhoe | D5: =COUNTIF('Voltooide coachings'!G:G,Tabel1[[#This Row],[Teamcoach]]) -> 39 | E5: =Tabel1[[#This Row],[Teamcoach]] -> Els Vanhoe
A6: =COUNTIF(Coaching!I3:I9884,Tabel1[[#This Row],[Teamcoach]]) -> 5 | B6: Dominique De Clercq | D6: =COUNTIF('Voltooide coachings'!G:G,Tabel1[[#This Row],[Teamcoach]]) -> 45 | E6: =Tabel1[[#This Row],[Teamcoach]] -> Dominique De Clercq
A7: =COUNTIF(Coaching!I4:I9885,Tabel1[[#This Row],[Teamcoach]]) -> 4 | B7: Steven Storm | D7: =COUNTIF('Voltooide coachings'!G:G,Tabel1[[#This Row],[Teamcoach]]) -> 21 | E7: =Tabel1[[#This Row],[Teamcoach]] -> Steven Storm
A8: =COUNTIF(Coaching!I4:I9886,Tabel1[[#This Row],[Teamcoach]]) -> 10 | B8: Lucie Vande Velde | D8: =COUNTIF('Voltooide coachings'!G:G,Tabel1[[#This Row],[Teamcoach]]) -> 30 | E8: =Tabel1[[#This Row],[Teamcoach]] -> Lucie Vande Velde
A9: =COUNTIF(Coaching!I4:I9887,Tabel1[[#This Row],[Teamcoach]]) -> 8 | B9: Kenneth De Rick | D9: =COUNTIF('Voltooide coachings'!G:G,Tabel1[[#This Row],[Teamcoach]]) -> 36 | E9: =Tabel1[[#This Row],[Teamcoach]] -> Kenneth De Rick

Sheet Vervolglijsten
A1: prioriteit | B1: hercoaching | C1: OT | D1: Bus/Tram | E1: instructeur | F1: werkpunten 1 | G1: werkpunten 2 | H1: beoordeling coaching | I1: SSF
A2: ja | B2: ja | C2: Gent Stad | D2: Bus | E2: Teamcoach | F2: Voertuigbeheersing | G2: Defensief rijden | H2: Zeer slecht | I2: ja
A3: ja, gepland | B3: nee | C3: Oost Vlaanderen Streek | D3: Tram | E3: 4691 Wim Van De Vijver | F3: Wegcode | G3: Positie baan | H3: Slecht | I3: nee
A4: gepland | E4: 4692 Dirk Verdonck (admin) | F4: Interne reglementering | G4: Aandoen haltes | H4: Onvoldoende
A5: nee | E5: 4707 Peter Schijvens | F5: Klantenzorg | G5: Voorrang | H5: Voldoende
E6: 6046 Joël De Maegd | F6: Geen opmerkingen | G6: Snelheid | H6: Goed
E7: 7848 Kathy Vermandel | G7: Andere weggebruikers | H7: Zeer goed
E8: 8538 Philippe Vandewalle | G8: Uniform
E9: 10905 Nourreddine Hamidou | G9: GSM
E10: 14537 Andy Gheerardijn | G10: Oortjes
E11: 16707 Wim Van Hende | G11: Te vroeg rijden
E12: 17552 Daisy De Geyter | G12: Vriendelijk
E13: 20541 Ruben Seghers | G13: Behulpzaam
E14: 20608 Joeri Mestdag | G14: Correcte info delen
E15: 22812 Tom De Clercq | G15: Geen opmerkingen
E16: 24577 Thierry De Vlieger
E17: 25875 Debby Verstockt
E18: 26202 Ward Desmet
E19: 27081 Guillaume Duré
E20: 29544 Roy Weyenbergh
E21: 29909 Ellen Lenders
E22: 31154 Jochen De Smaele
E23: 32710 Dirk Vanderstraeten

Sheet data Chauffeur
A1: PersoneelsNr | B1: Naam | C1: Voornaam | D1: Teamcoach | E1: Dienstrol | F1: OT
A2: 32458 | B2: Cifteoglu | C2: Sedat | D2: Els Dewulf | E2: B09 | F2: Gent stad
A3: 34198 | B3: Pelfrene | C3: Toby | D3: Els Vanhoe | E3: B09 | F3: Gent stad
A4: 34325 | B4: Eid | C4: Mathyn | D4: Steven Storm | E4: B09 | F4: Gent stad
A5: 35220 | B5: Akmese | C5: Ahmet | D5: Lucie Vande Velde | E5: B09 | F5: Gent stad
A6: 35055 | B6: Kocabas | C6: Abdülkadir | D6: Els Vanhoe | E6: B09 | F6: Gent stad
A7: 35107 | B7: Rotsaert | C7: Dominique | D7: Bart Van Der Beken | E7: B09 | F7: Gent stad
A8: 35493 | B8: van Turnhout | C8: Mariëlle | D8: Lucie Vande Velde | E8: B09 | F8: Gent stad
A9: 35490 | B9: Nguetto | C9: Brisco Romeo | D9: Steven Storm | E9: B09 | F9: Gent stad
A10: 35494 | B10: Rummens | C10: Maarten | D10: Els Vanhoe | E10: B09 | F10: Gent stad
A11: 35495 | B11: Razzaz | C11: Mahmoud | D11: Kenneth De Rick | E11: B09 | F11: Gent stad
A12: 35430 | B12: Vlaminck | C12: Dirk | D12: Els Vanhoe | E12: B09 | F12: Gent stad
A13: 35588 | B13: Smesman | C13: Glenn | D13: Lucie Vande Velde | E13: B09 | F13: Gent stad
... A598: 26265 | B598: Van Vlem | C598: Danny | D598: Christoff Rotty | E598: TW24 | F598: Gent stad
