Workbook

Sheet gesprekken per thema
A1: Onderwerp | B1: nummer | C1: Chauffeurnaam | D1: Datum | E1: Info | F1: Maand | G1: Jaar | H1: Aantal | I1: in dienst
A2: Ziekteverzuim: vergadering | B2: 3793 | C2: =VLOOKUP(B2,chauffeurslijst!A:B,2,0) -> Makelberge Michel | D2: 42395 | E2: verg: soc dienst neemt contact op | F2: =MONTH(D2) -> 1 | G2: =YEAR(D2) -> 2016 | H2: =COUNTIF(B:B,B2) -> 2 | I2: =VLOOKUP(B2,'controle 2022'!A:D,4,0) -> In dienst
A3: vroegrijden | B3: 3793 | C3: Makelberge Michel | D3: 43979 | E3: ED mail 12% extreem te vroeg en 32% te vroeg Totaal 44% te vroeg Covid 19? | F3: =MONTH(D3) -> 5 | G3: =YEAR(D3) -> 2020 | H3: =COUNTIF(B:B,B3) -> 2 | I3: =VLOOKUP(B3,'controle 2022'!A:D,4,0) -> In dienst
A4: Ongevallen/rijstijl | B4: 3926 | C4: De Clercq Marc | D4: 43580 | E4: Gesprek nav. ongeval eigen schade: bij binnenrijden sp 16 hermelijn2werkplaats steunbalk passerelle geraakt en geen melding van gemaakt. Besef van fout. In samenspraak met SH gn VVF maar bevestigingsbrief. | F4: =MONTH(D4) -> 4 | G4: =YEAR(D4) -> 2019 | H4: =COUNTIF(B:B,B4) -> 4 | I4: =VLOOKUP(B4,'controle 2022'!A:D,4,0) -> In dienst
A5: Vroegrijden: informeel | B5: 3926 | C5: De Clercq Marc | D5: 43812 | E5: Bart VDB: in de wandelgangen aangesproken mbt. slechte resultaten maand sept. tem. nov (steeds >30%), Hij weet dat hij er op moet letten en dat er werk aan de winkel is. Is een habitué in het te vroeg rijden. Bij een volgende vaststelling melding in chauffeurbeheer.... | F5: =MONTH(D5) -> 12 | G5: =YEAR(D5) -> 2019 | H5: =COUNTIF(B:B,B5) -> 4 | I5: =VLOOKUP(B5,'controle 2022'!A:D,4,0) -> In dienst
A6: Vroegrijden: informeel | B6: 3926 | C6: De Clercq Marc | D6: 43866 | E6: Bart VDB: maand dec. 2019 was beter 17,65% te vroege ritten waarvan 4,14% extremen.Echter jan. 2020 terug herval…35,71% te vroeg waarvan 1,79% extremen. Hem aangemoedigd dat hij het wel kan (zie dec.) en zijn uiterste best moet doen om zijn slechte gewoonte af te leren. In chauffeurbeheer gestoken onder coachinggesprekken. | F6: =MONTH(D6) -> 2 | G6: =YEAR(D6) -> 2020 | H6: =COUNTIF(B:B,B6) -> 4 | I6: =VLOOKUP(B6,'controle 2022'!A:D,4,0) -> In dienst
A7: Monitoring: te vroeg rijden | B7: 3926 | C7: De Clercq Marc | D7: 44384 | E7: Bart VDB Marc persoonlijk aangesproken: Wegens nieuwe aanspreekgrens >20% vanaf juni , nav. 22,75% totaal te vroeg (geen extremen). Marc heeft op vlak van te vroeg rijden wel een verleden maar geleden van jan. 2021 dat hij nog eens boven de 30% zat. Febr. tem. mei tss 10 & 20% steeds. Gevraagd nog een kleine inspanning te doen, immers hij heeft het afgelopen half jaar bewezen dat hij het wel kan. | F7: =MONTH(D7) -> 7 | G7: =YEAR(D7) -> 2021 | H7: =COUNTIF(B:B,B7) -> 4 | I7: =VLOOKUP(B7,'controle 2022'!A:D,4,0) -> In dienst
A8: Ziekteverzuim: vergadering | B8: 4193 | C8: =VLOOKUP(B8,chauffeurslijst!A:B,2,0) -> De Schepper Geert | D8: 42571 | E8: verg: opvolgen | F8: =MONTH(D8) -> 7 | G8: =YEAR(D8) -> 2016 | H8: =COUNTIF(B:B,B8) -> 6 | I8: =VLOOKUP(B8,'controle 2022'!A:D,4,0) -> In dienst
A9: Ziekteverzuim: vergadering | B9: 4193 | C9: =VLOOKUP(B9,chauffeurslijst!A:B,2,0) -> De Schepper Geert | D9: 42982 | E9: verg: opvolgen | F9: =MONTH(D9) -> 9 | G9: =YEAR(D9) -> 2017 | H9: =COUNTIF(B:B,B9) -> 6 | I9: =VLOOKUP(B9,'controle 2022'!A:D,4,0) -> In dienst
A10: Ziekteverzuim: informeel | B10: 4193 | C10: =VLOOKUP(B10,chauffeurslijst!A:B,2,0) -> De Schepper Geert | D10: 43038 | E10: Geert vroeg vroege diensten op 24, 25 en 26/10, daar is niet op ingegaan wegens maximaal aantal AD/maand bereikt; heeft zich ziek gezet op 24/10, herneemt vanaf 28/10 (maar had niet verwittigt dat hij herneemt) | F10: =MONTH(D10) -> 10 | G10: =YEAR(D10) -> 2017 | H10: =COUNTIF(B:B,B10) -> 6 | I10: =VLOOKUP(B10,'controle 2022'!A:D,4,0) -> In dienst
A11: Informeel | B11: 4193 | C11: =VLOOKUP(B11,chauffeurslijst!A:B,2,0) -> De Schepper Geert | D11: 43070 | E11: nav agressiegeval vorige week 2 weken tramdiensten | F11: =MONTH(D11) -> 12 | G11: =YEAR(D11) -> 2017 | H11: =COUNTIF(B:B,B11) -> 6 | I11: =VLOOKUP(B11,'controle 2022'!A:D,4,0) -> In dienst
A12: Ziekteverzuim | B12: 4193 | C12: =VLOOKUP(B12,chauffeurslijst!A:B,2,0) -> De Schepper Geert | D12: 43118 | E12: cr: standaardgesprek verzuim, voor RC al stappen ondernomen voor gesprek | F12: =MONTH(D12) -> 1 | G12: =YEAR(D12) -> 2018 | H12: =COUNTIF(B:B,B12) -> 6 | I12: =VLOOKUP(B12,'controle 2022'!A:D,4,0) -> In dienst
A13: informeel | B13: 4193 | C13: De Schepper Geert | D13: 44777 | E13: info YDC: gaat okt 2022 met pensioen | F13: =MONTH(D13) -> 8 | G13: =YEAR(D13) -> 2022 | H13: =COUNTIF(B:B,B13) -> 6 | I13: =VLOOKUP(B13,'controle 2022'!A:D,4,0) -> In dienst
A14: informeel | B14: 4276 | C14: Mostaert R | D14: 43726 | E14: LVV : aan zuid aangesproken door rudy omdat oude vrouw gevallen was bij het afstappen van de bus. Hij was er niet gerust in. Reiziger zei dat ze juist naar de dokter ging om de hoek. Ik heb die dokter gebeld en zei dat alles onder controle was. Rudy hiervan ingelicht. | F14: =MONTH(D14) -> 9 | G14: =YEAR(D14) -> 2019 | H14: =COUNTIF(B:B,B14) -> 1 | I14: =VLOOKUP(B14,'controle 2022'!A:D,4,0) -> In dienst
A15: Ziekteverzuim: vergadering | B15: 4440 | C15: =VLOOKUP(B15,chauffeurslijst!A:B,2,0) -> De Roo Jan | D15: 41582 | E15: verg 04/11/13: gesprek CR na volgende ZI | F15: =MONTH(D15) -> 11 | G15: =YEAR(D15) -> 2013 | H15: =COUNTIF(B:B,B15) -> 4 | I15: =VLOOKUP(B15,'controle 2022'!A:D,4,0) -> In dienst
A16: Ziekteverzuim: vergadering | B16: 4440 | C16: =VLOOKUP(B16,chauffeurslijst!A:B,2,0) -> De Roo Jan | D16: 42010 | E16: verg 06/01/15: zal nog tijdje tuis zijn, gaat niet goed met hem, soc dienst volgt op | F16: =MONTH(D16) -> 1 | G16: =YEAR(D16) -> 2015 | H16: =COUNTIF(B:B,B16) -> 4 | I16: =VLOOKUP(B16,'controle 2022'!A:D,4,0) -> In dienst
A17: Ziekteverzuim: informeel | B17: 4440 | C17: =VLOOKUP(B17,chauffeurslijst!A:B,2,0) -> De Roo Jan | D17: 42905 | E17: melding van soc dienst dat het niet goed gaat met Jan | F17: =MONTH(D17) -> 6 | G17: =YEAR(D17) -> 2017 | H17: =COUNTIF(B:B,B17) -> 4 | I17: =VLOOKUP(B17,'controle 2022'!A:D,4,0) -> In dienst
A18: Ziekteverzuim: informeel | B18: 4440 | C18: =VLOOKUP(B18,chauffeurslijst!A:B,2,0) -> De Roo Jan | D18: 42906 | E18: soc dienst: Ik ben bij Jan geweest gisteren. Zijn ziekte-attest is binnen. Volgens mij zal de afwezigheid niet zo lang duren als de vorige keer. Er werden nu al stappen gezet om de situatie aan te pakken. | F18: =MONTH(D18) -> 6 | G18: =YEAR(D18) -> 2017 | H18: =COUNTIF(B:B,B18) -> 4 | I18: =VLOOKUP(B18,'controle 2022'!A:D,4,0) -> In dienst
A19: Geldafgifte | B19: 4522 | C19: =VLOOKUP(B19,chauffeurslijst!A:B,2,0) -> Dierinck Charles | D19: 42017 | E19: 13/01/15: (tel.) zal vanaf nu de laatste werkdag storten ipv de eerste | F19: =MONTH(D19) -> 1 | G19: =YEAR(D19) -> 2015 | H19: =COUNTIF(B:B,B19) -> 2 | I19: =VLOOKUP(B19,'controle 2022'!A:D,4,0) -> In dienst
A20: Ziekteverzuim: vergadering | B20: 4522 | C20: =VLOOKUP(B20,chauffeurslijst!A:B,2,0) -> Dierinck Charles | D20: 42571 | E20: verg: soc dienst heeft contact gehad, operatie | F20: =MONTH(D20) -> 7 | G20: =YEAR(D20) -> 2016 | H20: =COUNTIF(B:B,B20) -> 2 | I20: =VLOOKUP(B20,'controle 2022'!A:D,4,0) -> In dienst
A21: Ziekteverzuim: vergadering | B21: 4523 | C21: =VLOOKUP(B21,chauffeurslijst!A:B,2,0) -> Lammens Eric | D21: 42571 | E21: verg: opvolgen | F21: =MONTH(D21) -> 7 | G21: =YEAR(D21) -> 2016 | H21: =COUNTIF(B:B,B21) -> 1 | I21: =VLOOKUP(B21,'controle 2022'!A:D,4,0) -> In dienst
A22: Evaluatie lijnverantw. | B22: 4525 | C22: Geert Vanthomme | D22: 44705 | E22: Bakken ervaring en kennis , die hij nog steeds met een bepaald enthousiasme overbrengt, Brengt heel veel verbetervoorstellen en gaat vlot in dialoog . Durft nogal licht ontvlambaar te zijn als er iets misloopt , maar weet dit even snel een plaats te geven. | F22: =MONTH(D22) -> 5 | G22: =YEAR(D22) -> 2022 | H22: =COUNTIF(B:B,B22) -> 1 | I22: =VLOOKUP(B22,'controle 2022'!A:D,4,0) -> In dienst
A23: Ziekteverzuim: vergadering | B23: 4608 | C23: =VLOOKUP(B23,chauffeurslijst!A:B,2,0) -> Steenbrugge Johan | D23: 41703 | E23: verg 05/03/14: geen actie | F23: =MONTH(D23) -> 3 | G23: =YEAR(D23) -> 2014 | H23: =COUNTIF(B:B,B23) -> 15 | I23: =VLOOKUP(B23,'controle 2022'!A:D,4,0) -> In dienst
A24: Ziekteverzuim: vergadering | B24: 4608 | C24: =VLOOKUP(B24,chauffeurslijst!A:B,2,0) -> Steenbrugge Johan | D24: 42109 | E24: verg 15/04/15: soc dienst kent het dossier en volgt op, is in behandeling | F24: =MONTH(D24) -> 4 | G24: =YEAR(D24) -> 2015 | H24: =COUNTIF(B:B,B24) -> 15 | I24: =VLOOKUP(B24,'controle 2022'!A:D,4,0) -> In dienst
A25: Ziekteverzuim: vergadering | B25: 4608 | C25: =VLOOKUP(B25,chauffeurslijst!A:B,2,0) -> Steenbrugge Johan | D25: 42571 | E25: verg: soc dienst volgt op | F25: =MONTH(D25) -> 7 | G25: =YEAR(D25) -> 2016 | H25: =COUNTIF(B:B,B25) -> 15 | I25: =VLOOKUP(B25,'controle 2022'!A:D,4,0) -> In dienst
A26: Ziekteverzuim | B26: 4608 | C26: =VLOOKUP(B26,chauffeurslijst!A:B,2,0) -> Steenbrugge Johan | D26: 42747 | E26: sw : samenloop van omstandigheden, geen reden tot verder verzuim, goed dossier | F26: =MONTH(D26) -> 1 | G26: =YEAR(D26) -> 2017 | H26: =COUNTIF(B:B,B26) -> 15 | I26: =VLOOKUP(B26,'controle 2022'!A:D,4,0) -> In dienst
A27: Ziekteverzuim: vergadering | B27: 4608 | C27: =VLOOKUP(B27,chauffeurslijst!A:B,2,0) -> Steenbrugge Johan | D27: 42754 | E27: verg: gesprek plaatsgevonden | F27: =MONTH(D27) -> 1 | G27: =YEAR(D27) -> 2017 | H27: =COUNTIF(B:B,B27) -> 15 | I27: =VLOOKUP(B27,'controle 2022'!A:D,4,0) -> In dienst
A28: Ziekteverzuim: vergadering | B28: 4608 | C28: =VLOOKUP(B28,chauffeurslijst!A:B,2,0) -> Steenbrugge Johan | D28: 43278 | E28: verg: gesprek inplannen - start traject | F28: =MONTH(D28) -> 6 | G28: =YEAR(D28) -> 2018 | H28: =COUNTIF(B:B,B28) -> 15 | I28: =VLOOKUP(B28,'controle 2022'!A:D,4,0) -> In dienst
A29: Ziekteverzuim | B29: 4608 | C29: =VLOOKUP(B29,chauffeurslijst!A:B,2,0) -> Steenbrugge Johan | D29: 43286 | E29: cr: start traject (rugklachten + thuis geweest met tennis- en golfelleboog) - verder blanco dossier | F29: =MONTH(D29) -> 7 | G29: =YEAR(D29) -> 2018 | H29: =COUNTIF(B:B,B29) -> 15 | I29: =VLOOKUP(B29,'controle 2022'!A:D,4,0) -> In dienst
A30: voorval met collega | B30: 4608 | C30: Steenbrugge Johan | D30: 43640 | E30: LVV : gesprek ivm voorval met collega (Idris Ozdemir) | F30: =MONTH(D30) -> 6 | G30: =YEAR(D30) -> 2019 | H30: =COUNTIF(B:B,B30) -> 15 | I30: =VLOOKUP(B30,'controle 2022'!A:D,4,0) -> In dienst
A31: Ziekteverzuim | B31: 4608 | C31: =VLOOKUP(B31,[1]chauffeurslijst!A:B,2,0) -> Steenbrugge Johan | D31: 44091 | E31: lvdv : telefonisch gesprek met Johan. Is reeds 1 maand thuis met rugklachten, kan pas op 21/09/20 terug naar zijn arts. Er zal waarschijnlijk een verlenging volgen. Hij heeft ook opnieuw last van zijn luchtwegen. | F31: =MONTH(D31) -> 9 | G31: =YEAR(D31) -> 2020 | H31: =COUNTIF(B:B,B31) -> 15 | I31: =VLOOKUP(B31,'controle 2022'!A:D,4,0) -> In dienst
A32: Ziekteverzuim | B32: 4608 | C32: =VLOOKUP(B32,[1]chauffeurslijst!A:B,2,0) -> Steenbrugge Johan | D32: 44147 | E32: LVV : telefonisch gesprek met Johan. Heeft terug verlenging gehad. Hij heeft last van jicht. | F32: =MONTH(D32) -> 11 | G32: =YEAR(D32) -> 2020 | H32: =COUNTIF(B:B,B32) -> 15 | I32: =VLOOKUP(B32,'controle 2022'!A:D,4,0) -> In dienst
A33: Ziekteverzuim | B33: 4608 | C33: =VLOOKUP(B33,[1]chauffeurslijst!A:B,2,0) -> Steenbrugge Johan | D33: 44159 | E33: LVV : gesprek ivm 4 keer ziek in 1 jaar, samen 153 dagen, bevestigd met brief | F33: =MONTH(D33) -> 11 | G33: =YEAR(D33) -> 2020 | H33: =COUNTIF(B:B,B33) -> 15 | I33: =VLOOKUP(B33,'controle 2022'!A:D,4,0) -> In dienst
A34: Ziekteverzuim | B34: 4608 | C34: =VLOOKUP(B34,[1]chauffeurslijst!A:B,2,0) -> Steenbrugge Johan | D34: 44741 | E34: gesprek SH + LVV : luisteren naar perspectieven naar herneming toe - langdurig ziek | F34: =MONTH(D34) -> 6 | G34: =YEAR(D34) -> 2022 | H34: =COUNTIF(B:B,B34) -> 15 | I34: =VLOOKUP(B34,'controle 2022'!A:D,4,0) -> In dienst
A35: Ziekteverzuim | B35: 4608 | C35: =VLOOKUP(B35,[1]chauffeurslijst!A:B,2,0) -> Steenbrugge Johan | D35: 45398 | E35: gesprek LVV : 4 x ziek/jaar, verder goed dossier | F35: =MONTH(D35) -> 4 | G35: =YEAR(D35) -> 2024 | H35: =COUNTIF(B:B,B35) -> 15 | I35: =VLOOKUP(B35,'controle 2022'!A:D,4,0) -> In dienst
A36: verzuim : informeel | B36: 4608 | C36: =VLOOKUP(B36,[1]chauffeurslijst!A:B,2,0) -> Steenbrugge Johan | D36: 45593 | E36: tel LVV: Johan had eerst een attest tem 26/10/2024 en had al verwittigd dat hij het werk zou hervatten. Zijn rug is opnieuw geblokeerd en hij krijgt zware medicatie en moet veel rusten | F36: =MONTH(D36) -> 10 | G36: =YEAR(D36) -> 2024 | H36: =COUNTIF(B:B,B36) -> 15 | I36: =VLOOKUP(B36,'controle 2022'!A:D,4,0) -> In dienst
A37: verzuim : informeel | B37: 4608 | C37: =VLOOKUP(B37,[1]chauffeurslijst!A:B,2,0) -> Steenbrugge Johan | D37: 45999 | E37: tel. LVV: Johan is ziek van 10/11 tem 03/12/2025 met rugpijn. Hij heeft het werk hervat maar na 3 dagen opnieuw onhoudbare pijn in rug. Ondertussen attest tem 19/12/2025. Hij moet hiervoor onder de MRI gaan. Dit kan pas op 28/02/2026 | F37: =MONTH(D37) -> 12 | G37: =YEAR(D37) -> 2025
A38: Geldafgifte | B38: 4624 | C38: =VLOOKUP(B38,chauffeurslijst!A:B,2,0) -> Declercq Erik | D38: 40471 | E38: elke barema storten | F38: =MONTH(D38) -> 10 | G38: =YEAR(D38) -> 2010 | H38: =COUNTIF(B:B,B38) -> 12 | I38: =VLOOKUP(B38,'controle 2022'!A:D,4,0) -> In dienst
A39: Geldafgifte | B39: 4624 | C39: =VLOOKUP(B39,chauffeurslijst!A:B,2,0) -> Declercq Erik | D39: 41232 | E39: (CR + IVC): laatste kans (ziekte, TL en geldafgifte), dagelijks storten | F39: =MONTH(D39) -> 11 | G39: =YEAR(D39) -> 2012 | H39: =COUNTIF(B:B,B39) -> 12 | I39: =VLOOKUP(B39,'controle 2022'!A:D,4,0) -> In dienst
A40: Ziekteverzuim | B40: 4624 | C40: =VLOOKUP(B40,chauffeurslijst!A:B,2,0) -> Declercq Erik | D40: 41232 | E40: 19/11/12 (CR + IVC): laatste kans (ziekte, TL en geldafgifte) | F40: =MONTH(D40) -> 11 | G40: =YEAR(D40) -> 2012 | H40: =COUNTIF(B:B,B40) -> 12 | I40: =VLOOKUP(B40,'controle 2022'!A:D,4,0) -> In dienst
...

Sheet controle 2022
A1: PersoneelsNr | B1: Naam | C1: Voornaam | D1: RedenUitDienst
A2: 10067 | B2: Toumi | C2: Sabri | D2: In dienst
A3: 10150 | B3: Vandenbogaerde | C3: Tony | D3: In dienst
A4: 10171 | B4: Robbe | C4: Sofie | D4: Ontslagnemer
A5: 10299 | B5: Batslé | C5: Dieter | D5: In dienst
A6: 10324 | B6: Eggermont | C6: Wim | D6: In dienst
A7: 10326 | B7: Lefebvre | C7: Olivier | D7: In dienst
A8: 10549 | B8: Bogaert | C8: Ivan | D8: Ontslagnemer
A9: 1075 | B9: De Mol | C9: Raphael | D9: (Brug-)pensioen
A10: 10782 | B10: De Kee | C10: Ina | D10: In dienst
A11: 10903 | B11: De Paepe | C11: Jeroen | D11: Mutatie
A12: 11019 | B12: Gevaert | C12: Ignace | D12: (Brug-)pensioen
A13: 11021 | B13: Seeuws | C13: Marnic | D13: In dienst
... A888: 9979 | B888: Loots | C888: Wim | D888: In dienst

Sheet uit dienst
A1: Opvolgen | B1: Dienstnr | C1: Naam | E1: Opmerking | F1: reden uit dienst
A2: Ziekteverzuim | B2: 1814 | C2: Verhamme Andre | E2: verg 05/03/14: geen actie | F2: pensioen
A3: Ziekteverzuim | B3: 2500 | C3: Bastiaen Eric | E3: verg 27/07/15: opvolgen, operatie | F3: pensioen
A4: Ongevallen/rijstijl | B4: 2500 | C4: Bastiaen Eric | D4: 42571 | E4: tweede signaal op korte tijd ivm rijstijl, coaching gevraagd, ook soc dienst ingelicht in kader van vorig signaal van Eric, vermoedelijk iets meer aan de hand | F4: pensioen
A5: Ziekteverzuim | B5: 2651 | C5: Baeten Willy | E5: 08/04/09, | F5: pensioen
A6: Ongevallen/rijstijl | B6: 2920 | C6: Speeckaert Rudy | E6: 24/09/11: dodelijk ongeval Rooigemlaan | F6: pensioen
A7: Geldafgifte | B7: 3134 | C7: Bracke Dirk | E7: 01/08/11: elke barema storten; tel. 31/01/12: blijft met achterstand van 116,15 euro; brief 20/02/12: nog steeds niet in orde, storten tegen 29/02; nazicht kas op 2/08/13: ok | F7: pensioen
A8: Ziekteverzuim | B8: 3141 | C8: Hellebaut Franky | E8: 07/01/09, 15/05/09 (JB), | F8: pensioen
A9: Ziekteverzuim | B9: 3239 | C9: Dewispelaere Jean-Pierre | E9: 13/08/12, | F9: pensioen
A10: Ziekteverzuim | B10: 3240 | C10: Ide Dirk | E10: 30/09/09, 30/11/09 (MF), 21/05/10 (JB), 15/11/10 (JB) | F10: gedwongen mutatie DES
A11: Geldafgifte | B11: 3240 | C11: Ide Dirk | E11: 30/11/09: laatste kans MF; 21/05/10 met JB: niet meer in negatief staan; 15/11/10 met JB: laatste verwittiging, dagelijks storten; 17/02/12: tel., herinnerd aan de afspraken; 28/02/12: herinnerd aan feit dat hij elke dag moet storten; 13/06/12: gedwongen mutatie ipv ontslag(CR +IVC) | F11: gedwongen mutatie DES
A12: Ongevallen/rijstijl | B12: 3240 | C12: Ide Dirk | E12: gesprek SH nav niet gebruikte halterem (2x op korte tijd) | F12: gedwongen mutatie DES
A13: Ongevallen/rijstijl | B13: 3437 | C13: Damoiseaux Marc | E13: 20/11/12: einde opvolging rijschool (pos.) | F13: pensioen
A14: Ziekteverzuim | B14: 3594 | C14: Vanlancker Jean-Pierre | E14: verg 05/03/14: steeds zelfde problematiek | F14: pensioen
A15: Ziekteverzuim: vergadering | B15: 3670 | C15: =VLOOKUP(B15,chauffeurslijst!A:B,2,0) -> Van Geyt Michael | D15: 42048 | E15: verg 13/02/15: chronische problemen, geen beterschap in zicht | F15: pensioen
A16: Ziekteverzuim | B16: 3690 | C16: =VLOOKUP(B16,chauffeurslijst!A:B,2,0) -> Galens Georges | E16: verg 28/07/15: ingreep ondergaan, wil in pensioen gaan gezien zijn toestand | F16: AZV2
A17: Ziekteverzuim | B17: 3690 | C17: =VLOOKUP(B17,chauffeurslijst!A:B,2,0) -> Galens Georges | E17: 07/10/15: Georges kwam langs ikv een eventuele werkhervatting bij de arbeidsgeneesheer, voor ev aangepast werk, maar er is nog geen sprake van werkhervatting. | F17: AZV2
A18: Ziekteverzuim | B18: 3690 | C18: =VLOOKUP(B18,chauffeurslijst!A:B,2,0) -> Galens Georges | D18: 42395 | E18: verg: arbeidsgeneesheer geen voorstander van hervatting | F18: AZV2
A19: Ziekteverzuim | B19: 3690 | C19: =VLOOKUP(B19,chauffeurslijst!A:B,2,0) -> Galens Georges | D19: 42583 | E19: verg: hervatten, ook aangepast werk, is weinig waarschijnlijk, ook volgens arbeidsgeneesheer. Vermoedelijk AZV2 vanaf 4/02/2017. | F19: AZV2
A20: Ziekteverzuim | B20: 3690 | C20: =VLOOKUP(B20,chauffeurslijst!A:B,2,0) -> Galens Georges | D20: 42754 | E20: verg: zal op AZV2 gaan op 4 feb 2017, kan niet van ZI op brugpensioen (nek - evenwichtsstoornissen) | F20: AZV2
A21: Ziekteverzuim | B21: 3744 | C21: D'Hertoghe Luc | E21: verg 05/03/14: zware problematiek, zal vermoedelijk niet snel terugkomen | F21: overleden
A22: Ziekteverzuim | B22: 3769 | C22: Vandeveire Jean Pierre | E22: 29/08/12, verg 06/05/14: pensioen aangevraagd; 29/09/14 (informeel): last van hernia; | F22: pensioen
A23: Ziekteverzuim | B23: 3769 | C23: Vandeveire Jean Pierre | E23: verg 15/04/15: gaat in pensioen begin 2016, geen actie; | F23: pensioen
A24: Ziekteverzuim | B24: 3769 | C24: Vandeveire Jean Pierre | E24: verg 27/07/15: geen actie | F24: pensioen
A25: Ziekteverzuim | B25: 3780 | C25: Van Eeghem Martin | E25: verg 05/03/14: geen actie | F25: pensioen
A26: Ziekteverzuim | B26: 3860 | C26: Verschraegen Daniël | E26: 17/01/12, verg 04/11/13: sociale dienst neemt contact op, verg 05/03/14: patroon zal blijven, nog eens apart te bespreken; verg 06/05/14: gesprek CR op 07/05/14, brugpensioen suggereren; 07/05/14; | F26: kasdienst en pensioen
A27: Te laat komen | B27: 3860 | C27: Verschraegen Daniël | E27: 17/01/12; nazicht 21/01/14: 6 nieuwe vvf, 2 in 2012 en 4 in 2013; 07/05/14; 27/11/14 (slaapt slecht door pijn) | F27: kasdienst en pensioen
A28: Ziekteverzuim | B28: 3860 | C28: Verschraegen Daniël | E28: verg 27/07/15: brugpensioen aangevraagd, werkt 100%, helpt niet voor zijn periodes | F28: kasdienst en pensioen
A29: Ziekteverzuim | B29: 3860 | C29: Verschraegen Daniël | D29: 42395 | E29: verg: via mesor voorstel voor 3e job, zal vanaf juni naar magazijn of elders kunnen om dan in brugpensioen te kunnen gaan, vermoedelijk ziek tot aangepast werk | F29: kasdienst en pensioen
A30: Ziekteverzuim | B30: 3948 | C30: Lagae Rudi | E30: 12/02/10, 02/10/12, 20/03/13 (3 nieuwe periodes na vorig gesprek, waarvan 1 AO), langdurige periode na gesprek: 10/05/13 tot 26/07/13; verg 04/11/13: sociale dienst neemt contact; verg 05/03/14: dossier voorbereiden; verg 06/05/14: gesprek IVC; 04/07/14 (IVC + CR): vermoedelijk nog operatie nodig (knieprothese), moet bij herneming goed dossier worden en blijven; 24/12/14: mailtje gestuurd met vraag hoe het is; | F30: aangepast werk en nadien brugpensioen
A31: Ziekteverzuim | B31: 3948 | C31: Lagae Rudi | E31: 02/01/15: antwoord: verlenging; | F31: aangepast werk en nadien brugpensioen
A32: Ziekteverzuim | B32: 3948 | C32: Lagae Rudi | E32: verg 13/02/15: nog niet hernomen, opvolgen; | F32: aangepast werk en nadien brugpensioen
A33: Ziekteverzuim | B33: 3948 | C33: Lagae Rudi | E33: verg 28/07/15: opvolgen, pensioen aangevraagd? | F33: aangepast werk en nadien brugpensioen
A34: Geldafgifte | B34: 3948 | C34: Lagae Rudi | E34: 02/10/12: elke barema storten, 20/03/13: stort elke barema, nazicht kas 2/08/13: openstaand saldo, al een tijdje ziek, ok voor brief; 04/07/14 (IVC + CR): vermoedelijk nog operatie nodig (knieprothese), moet bij herneming goed dossier worden en blijven | F34: aangepast werk en nadien brugpensioen
A35: Te laat komen | B35: 3948 | C35: Lagae Rudi | E35: 02/10/12, 20/03/13: na vorig gesprek 2x te laat gekomen, waarvan 1 door misverstand met verwisseling, kijkt nu op website; nazicht 21/01/14: 2 nieuwe vvf; 04/07/14 (IVC + CR): vermoedelijk nog operatie nodig (knieprothese), moet bij herneming goed dossier worden en blijven | F35: aangepast werk en nadien brugpensioen
A36: Onregelmatigheden | B36: 3964 | C36: Vaneeckhaute Philippe | E36: 12/11/14: nav verkoop ticketten op voertuig | F36: pensioen
A37: Ziekteverzuim | B37: 3986 | C37: =VLOOKUP(B37,chauffeurslijst!A:B,2,0) -> Decaluwe Dirk | E37: 20/10/09, 08/03/10; | F37: pensioen
A38: Te laat komen | B38: 3986 | C38: =VLOOKUP(B38,chauffeurslijst!A:B,2,0) -> Decaluwe Dirk | E38: 26/05/14: niet op gesprek gekomen, brief gestuurd | F38: pensioen
A39: Ziekteverzuim | B39: 3986 | C39: =VLOOKUP(B39,chauffeurslijst!A:B,2,0) -> Decaluwe Dirk | E39: verg 15/04/15: geen actie; | F39: pensioen
A40: Ziekteverzuim | B40: 3986 | C40: =VLOOKUP(B40,chauffeurslijst!A:B,2,0) -> Decaluwe Dirk | E40: verg 27/07/15: geen actie | F40: pensioen
...

Sheet statistiek
A1: Jaar | B1: 2018
A3: Aantal van Onderwerp | B3: Kolomlabels
A4: Rijlabels | B4: 1 | C4: 2 | D4: 3 | E4: 4 | F4: 5 | G4: 6 | H4: 7 | I4: 8 | J4: 9 | K4: 12 | L4: Eindtotaal
A5: Ziekteverzuim: vergadering | B5: 15 | C5: 10 | F5: 1 | G5: 114 | H5: 1 | J5: 2 | L5: 143
A6: Ziekteverzuim: informeel | B6: 11 | C6: 21 | D6: 25 | E6: 20 | F6: 12 | G6: 8 | H6: 21 | I6: 11 | J6: 1 | L6: 130
A7: Ziekteverzuim | B7: 10 | C7: 7 | D7: 10 | E7: 2 | F7: 2 | G7: 3 | H7: 17 | I7: 4 | J7: 2 | L7: 57
A8: Evaluatiegesprek | B8: 5 | C8: 3 | D8: 5 | E8: 5 | F8: 5 | G8: 1 | H8: 1 | I8: 4 | L8: 29
A9: Mesor | B9: 2 | C9: 1 | D9: 2 | E9: 2 | F9: 5 | G9: 6 | I9: 7 | J9: 1 | K9: 1 | L9: 27
A10: Algemeen functioneren | B10: 5 | C10: 2 | D10: 7 | F10: 3 | G10: 3 | H10: 2 | I10: 2 | J10: 1 | L10: 25
A11: Onregelmatigheden | B11: 2 | C11: 5 | D11: 1 | E11: 1 | F11: 3 | L11: 12
A12: Mondelinge opmerkingen | B12: 4 | C12: 1 | E12: 1 | F12: 2 | G12: 1 | H12: 1 | I12: 1 | J12: 1 | L12: 12
A13: Klantenreacties | B13: 3 | D13: 3 | E13: 3 | G13: 1 | H13: 1 | L13: 11
A14: Ongevallen/rijstijl | B14: 2 | D14: 2 | E14: 2 | F14: 3 | I14: 1 | L14: 10
A15: Geldafgifte | B15: 1 | C15: 2 | D15: 1 | E15: 1 | F15: 1 | I15: 1 | L15: 7
A16: Ziekteverzuim | H16: 3 | I16: 2 | L16: 5
A17: ADM | G17: 2 | I17: 1 | J17: 2 | L17: 5
A18: Informeel | D18: 2 | E18: 2 | L18: 4
A19: Ziekteverzuim | G19: 3 | L19: 3
A20: Opleiding | C20: 2 | L20: 2
A21: Conflict | H21: 1 | I21: 1 | L21: 2
A22: Arbeidsongevallen | E22: 1 | H22: 1 | L22: 2
A23: agressie | I23: 2 | L23: 2
A24: Arbeidsongeval | I24: 1 | L24: 1
A25: Afwezigheid | J25: 1 | L25: 1
A26: Ziekteverzuim / geldafgifte | I26: 1 | L26: 1
A27: Vroegrijden | C27: 1 | L27: 1
A28: Diverse | C28: 1 | L28: 1
A29: Monitoring | H29: 1 | L29: 1
A30: Te laat komen | G30: 1 | L30: 1
A31: Roken | D31: 1 | L31: 1
A32: Eindtotaal | B32: 60 | C32: 56 | D32: 59 | E32: 40 | F32: 37 | G32: 143 | H32: 50 | I32: 39 | J32: 11 | K32: 1 | L32: 496
A33: zonder ZI: verg en zonder mesor | B33: =GETPIVOTDATA("Onderwerp",$A$3,"Maand",1)-GETPIVOTDATA("Onderwerp",$A$3,"Onderwerp","Ziekteverzuim: vergadering","Maand",1)-GETPIVOTDATA("Onderwerp",$A$3,"Onderwerp","Mesor","Maand",1) -> 43 | C33: =GETPIVOTDATA("Onderwerp",$A$3,"Maand",2)-GETPIVOTDATA("Onderwerp",$A$3,"Onderwerp","Ziekteverzuim: informeel","Maand",2)-GETPIVOTDATA("Onderwerp",$A$3,"Onderwerp","Mesor","Maand",2) -> 34 | D33: =GETPIVOTDATA("Onderwerp",$A$3,"Maand",3)-GETPIVOTDATA("Onderwerp",$A$3,"Onderwerp","Mesor","Maand",3) -> 57 | E33: =GETPIVOTDATA("Onderwerp",$A$3,"Maand",4)-GETPIVOTDATA("Onderwerp",$A$3,"Onderwerp","Mesor","Maand",4) -> 38 | F33: =GETPIVOTDATA("Onderwerp",$A$3,"Maand",6)-GETPIVOTDATA("Onderwerp",$A$3,"Onderwerp","Ziekteverzuim: vergadering","Maand",6)-GETPIVOTDATA("Onderwerp",$A$3,"Onderwerp","Mesor","Maand",6) -> 23 | G33: =GETPIVOTDATA("Onderwerp",$A$3,"Maand",2)-GETPIVOTDATA("Onderwerp",$A$3,"Onderwerp","Ziekteverzuim: informeel","Maand",2)-GETPIVOTDATA("Onderwerp",$A$3,"Onderwerp","Mesor","Maand",2) -> 34 | H33: =GETPIVOTDATA("Onderwerp",$A$3,"Maand",7)-GETPIVOTDATA("Onderwerp",$A$3,"Onderwerp","Ziekteverzuim: vergadering","Maand",7) -> 49 | I33: =GETPIVOTDATA("Onderwerp",$A$3,"Maand",8)-GETPIVOTDATA("Onderwerp",$A$3,"Onderwerp","Mesor","Maand",8) -> 32

Sheet chauffeurslijst
A1: PersoneelsNr | B1: Naam
A2: 10067 | B2: Toumi Sabri
A3: 10150 | B3: Vandenbogaerde Tony
A4: 10171 | B4: Robbe Sofie
A5: 10299 | B5: Batslé Dieter
A6: 10324 | B6: Eggermont Wim
A7: 10326 | B7: Lefebvre Olivier
A8: 10549 | B8: Bogaert Ivan
A9: 1075 | B9: De Mol Raphael
A10: 10782 | B10: De Kee Ina
A11: 10903 | B11: De Paepe Jeroen
A12: 11019 | B12: Gevaert Ignace
A13: 11021 | B13: Seeuws Marnic
... A618: 34044 | B618: Wieme Kevin
A619: 34178 | B619: Vanhouteghem Jonas | C619: =VALUE(A619) -> 34178
A620: 34180 | B620: Van den Daele Jan | C620: =VALUE(A620) -> 34180
A621: 34198 | B621: Pelfrene Toby | C621: =VALUE(A621) -> 34198
A622: 34286 | B622: Ghani Mozamil | C622: =VALUE(A622) -> 34286
A623: 34294 | B623: Jagne Momodou | C623: =VALUE(A623) -> 34294
A624: 34312 | B624: Sari Halil | C624: =VALUE(A624) -> 34312
A625: 34313 | B625: Baert Peter | C625: =VALUE(A625) -> 34313
A626: 34325 | B626: Eid Mahammud | C626: =VALUE(A626) -> 34325
A627: 34328 | B627: Kerremans Jürgen | C627: =VALUE(A627) -> 34328
A628: 34351 | B628: Callant Dieter | C628: =VALUE(A628) -> 34351
A629: 34385 | B629: Goossens Wesley | C629: =VALUE(A629) -> 34385
A630: 34445 | B630: Wulleput Illya | C630: =VALUE(A630) -> 34445
... A690: 35670 | B690: Krak Jerry Ruben | C690: =VALUE(A690) -> 35670
A691: 35671 | B691: Verpoest Wesley | C691: 33142
A692: 35709 | B692: El Gasmi Sami
A693: 35714 | B693: Stubbe Jarne
A694: 35753 | B694: Bagseven Mikail
A695: 35761 | B695: Simsek Huseyin
A696: 35786 | B696: Braet Juanito
A697: 35816 | B697: Guyssens Peter
A698: 35850 | B698: Mouton Jim
A699: 35858 | B699: Kalhor Kamran
A700: 35862 | B700: Van Damme Patrick
A701: 35939 | B701: Vermeire Timothy
A702: 3594 | B702: Van Lancker Jean-Pierre
A703: 35962 | B703: Mouhine Marouane
...

Sheet Gesprekken 2015
A1: Aard | B1: dienstnr | C1: naam | D1: datum gesprek | E1: met wie | F1: afspraak | G1: jaar
A2: Ziekteverzuim | B2: 29476 | C2: =IF(ISNA(VLOOKUP(B2,chauffeurslijst!A:B,2,0)),"",(VLOOKUP(B2,chauffeurslijst!A:B,2,0))) | D2: 42016 | E2: IVC + CR | F2: ontslag | G2: =YEAR(D2) -> 2015
A3: Ziekteverzuim | B3: 29369 | C3: =IF(ISNA(VLOOKUP(B3,chauffeurslijst!A:B,2,0)),"",(VLOOKUP(B3,chauffeurslijst!A:B,2,0))) -> Vyncke Sissi | D3: 42017 | E3: CR | F3: ingesproken op voice mail dat het zo niet kan blijven duren | G3: =YEAR(D3) -> 2015
A4: Ziekteverzuim | B4: 21426 | C4: =IF(ISNA(VLOOKUP(B4,chauffeurslijst!A:B,2,0)),"",(VLOOKUP(B4,chauffeurslijst!A:B,2,0))) -> Housiaux Yves | D4: 42023 | E4: CR | F4: zelf aangevraagd | G4: =YEAR(D4) -> 2015
A5: Ziekteverzuim | B5: 23881 | C5: =IF(ISNA(VLOOKUP(B5,chauffeurslijst!A:B,2,0)),"",(VLOOKUP(B5,chauffeurslijst!A:B,2,0))) -> Cornette Jurgen | D5: 42023 | E5: IVC + CR | F5: gunstige evaluatie | G5: =YEAR(D5) -> 2015
A6: Ziekteverzuim | B6: 11744 | C6: =IF(ISNA(VLOOKUP(B6,chauffeurslijst!A:B,2,0)),"",(VLOOKUP(B6,chauffeurslijst!A:B,2,0))) -> De Pauw Dorothy | D6: 42023 | E6: IVC + CR | F6: gunstige evaluatie | G6: =YEAR(D6) -> 2015
A7: Ziekteverzuim | B7: 15087 | C7: =IF(ISNA(VLOOKUP(B7,chauffeurslijst!A:B,2,0)),"",(VLOOKUP(B7,chauffeurslijst!A:B,2,0))) -> Kiliç Halil | D7: 42024 | E7: CR | F7: tijdens gesprek TL | G7: =YEAR(D7) -> 2015
A8: Ziekteverzuim | B8: 20479 | C8: =IF(ISNA(VLOOKUP(B8,chauffeurslijst!A:B,2,0)),"",(VLOOKUP(B8,chauffeurslijst!A:B,2,0))) | D8: 42026 | E8: VL + CR | F8: zelf aangevraagd | G8: =YEAR(D8) -> 2015
A9: Ziekteverzuim | B9: 27151 | C9: =IF(ISNA(VLOOKUP(B9,chauffeurslijst!A:B,2,0)),"",(VLOOKUP(B9,chauffeurslijst!A:B,2,0))) -> De Winter Lorenzo | D9: 42026 | E9: SW | F9: gesprek over algemeen functioneren bij hervatting (deeltijds) vanaf 01/02/2015 | G9: =YEAR(D9) -> 2015
A10: Ziekteverzuim | B10: 28460 | C10: =IF(ISNA(VLOOKUP(B10,chauffeurslijst!A:B,2,0)),"",(VLOOKUP(B10,chauffeurslijst!A:B,2,0))) -> Özcam Halil | D10: 42031 | E10: CR | G10: =YEAR(D10) -> 2015
A11: Ziekteverzuim | B11: 25220 | C11: Elcin Huseyin Kursat | D11: 42086 | E11: IVC + CR | G11: =YEAR(D11) -> 2015
A12: Ziekteverzuim | B12: 14425 | C12: Vandaele Thibaut | D12: 42089 | E12: CR | G12: =YEAR(D12) -> 2015
A13: Ziekteverzuim | B13: 23164 | C13: Tillieu Patricia | D13: 42093 | E13: CR | F13: informeel | G13: =YEAR(D13) -> 2015
A14: Ziekteverzuim | B14: 29369 | C14: =IF(ISNA(VLOOKUP(B14,chauffeurslijst!A:B,2,0)),"",(VLOOKUP(B14,chauffeurslijst!A:B,2,0))) -> Vyncke Sissi | D14: 42115 | E14: SW | F14: ziekteverzuim besproken naar aanleiding van evaluatiegesprek 6 maanden | G14: =YEAR(D14) -> 2015
A15: Ziekteverzuim | B15: 26847 | C15: =IF(ISNA(VLOOKUP(B15,chauffeurslijst!A:B,2,0)),"",(VLOOKUP(B15,chauffeurslijst!A:B,2,0))) -> De Meester David | D15: 42135 | E15: SW | G15: =YEAR(D15) -> 2015
A16: Ziekteverzuim | B16: 22051 | C16: Pospiech Marcin | D16: 42137 | E16: CR | G16: =YEAR(D16) -> 2015
A17: Ziekteverzuim | B17: 27577 | C17: De Meester Johan | D17: 43238 | E17: CR | G17: =YEAR(D17) -> 2018
A18: Ziekteverzuim | B18: 19249 | C18: Odaci Kadir | D18: 42142 | E18: CR | G18: =YEAR(D18) -> 2015
A19: Ziekteverzuim | B19: 20541 | C19: Seghers Ruben | D19: 42143 | E19: CR | G19: =YEAR(D19) -> 2015
A20: Ziekteverzuim | B20: 27672 | C20: =IF(ISNA(VLOOKUP(B20,chauffeurslijst!A:B,2,0)),"",(VLOOKUP(B20,chauffeurslijst!A:B,2,0))) -> Criel Veronique | D20: 42143 | E20: SW | G20: =YEAR(D20) -> 2015
A21: Ziekteverzuim | B21: 25933 | C21: =IF(ISNA(VLOOKUP(B21,chauffeurslijst!A:B,2,0)),"",(VLOOKUP(B21,chauffeurslijst!A:B,2,0))) -> Mechthold Ralf | D21: 42144 | E21: SW | G21: =YEAR(D21) -> 2015
A22: Ziekteverzuim | B22: 14337 | C22: =IF(ISNA(VLOOKUP(B22,chauffeurslijst!A:B,2,0)),"",(VLOOKUP(B22,chauffeurslijst!A:B,2,0))) -> Cetinkaya Tuncay | D22: 42144 | E22: SW | F22: zie ook geldafgifte | G22: =YEAR(D22) -> 2015
A23: Ziekteverzuim | B23: 15184 | C23: Sven Walenta | D23: 42144 | E23: CR | G23: =YEAR(D23) -> 2015
A24: Ziekteverzuim | B24: 26524 | C24: Cynthia Bolle | D24: 42144 | E24: CR | G24: =YEAR(D24) -> 2015
A25: Ziekteverzuim | B25: 27719 | C25: =IF(ISNA(VLOOKUP(B25,chauffeurslijst!A:B,2,0)),"",(VLOOKUP(B25,chauffeurslijst!A:B,2,0))) -> Van der Cruyssen Annik | D25: 42150 | E25: SW | G25: =YEAR(D25) -> 2015
A26: Ziekteverzuim | B26: 26137 | C26: =IF(ISNA(VLOOKUP(B26,chauffeurslijst!A:B,2,0)),"",(VLOOKUP(B26,chauffeurslijst!A:B,2,0))) -> Hublau Roland | D26: 42163 | E26: CR | G26: =YEAR(D26) -> 2015
A27: Ziekteverzuim | B27: 16281 | C27: =IF(ISNA(VLOOKUP(B27,chauffeurslijst!A:B,2,0)),"",(VLOOKUP(B27,chauffeurslijst!A:B,2,0))) -> Omey Geert | D27: 42172 | E27: CR | F27: na LZ | G27: =YEAR(D27) -> 2015
A28: Ziekteverzuim | B28: 20373 | C28: =IF(ISNA(VLOOKUP(B28,chauffeurslijst!A:B,2,0)),"",(VLOOKUP(B28,chauffeurslijst!A:B,2,0))) -> Dhooge Wim | D28: 42172 | E28: CR | F28: na LZ | G28: =YEAR(D28) -> 2015
A29: Ziekteverzuim | B29: 16897 | C29: =IF(ISNA(VLOOKUP(B29,chauffeurslijst!A:B,2,0)),"",(VLOOKUP(B29,chauffeurslijst!A:B,2,0))) -> VandenDaele Andy | D29: 42181 | E29: CR | G29: =YEAR(D29) -> 2015
A30: Ziekteverzuim | B30: 20738 | C30: =IF(ISNA(VLOOKUP(B30,chauffeurslijst!A:B,2,0)),"",(VLOOKUP(B30,chauffeurslijst!A:B,2,0))) | D30: 42193 | E30: CR | F30: ontslag | G30: =YEAR(D30) -> 2015
A31: Ziekteverzuim | B31: 28828 | C31: =IF(ISNA(VLOOKUP(B31,chauffeurslijst!A:B,2,0)),"",(VLOOKUP(B31,chauffeurslijst!A:B,2,0))) -> Tek Fatih | D31: 42227 | E31: SW | F31: ziekte/ algemeen functioneren | G31: =YEAR(D31) -> 2015
A32: Ziekteverzuim | B32: 26046 | C32: =IF(ISNA(VLOOKUP(B32,chauffeurslijst!A:B,2,0)),"",(VLOOKUP(B32,chauffeurslijst!A:B,2,0))) -> Vanden Veegaete Münir | D32: 42194 | E32: CR | F32: op eigen initiatief | G32: =YEAR(D32) -> 2015
A33: Ziekteverzuim | B33: 11744 | C33: =IF(ISNA(VLOOKUP(B33,chauffeurslijst!A:B,2,0)),"",(VLOOKUP(B33,chauffeurslijst!A:B,2,0))) -> De Pauw Dorothy | D33: 42194 | E33: IVC + CR | G33: =YEAR(D33) -> 2015
A34: Ziekteverzuim | B34: 28830 | C34: =IF(ISNA(VLOOKUP(B34,chauffeurslijst!A:B,2,0)),"",(VLOOKUP(B34,chauffeurslijst!A:B,2,0))) -> Isiklar Okan | D34: 42227 | E34: SW | G34: =YEAR(D34) -> 2015
A35: Ziekteverzuim | B35: 10903 | C35: =IF(ISNA(VLOOKUP(B35,chauffeurslijst!A:B,2,0)),"",(VLOOKUP(B35,chauffeurslijst!A:B,2,0))) -> De Paepe Jeroen | D35: 42237 | E35: SW | F35: ziekte/algemeen functioneren | G35: =YEAR(D35) -> 2015
A36: Ziekteverzuim | B36: 27606 | C36: =IF(ISNA(VLOOKUP(B36,chauffeurslijst!A:B,2,0)),"",(VLOOKUP(B36,chauffeurslijst!A:B,2,0))) -> Peeters Sebastiaan | D36: 42199 | E36: IVC + CR | G36: =YEAR(D36) -> 2015
A37: Ziekteverzuim | B37: 20303 | C37: =IF(ISNA(VLOOKUP(B37,chauffeurslijst!A:B,2,0)),"",(VLOOKUP(B37,chauffeurslijst!A:B,2,0))) -> Ettaibi Moulay Abdelrani | D37: 42207 | E37: CR | F37: zelf gebeld | G37: =YEAR(D37) -> 2015
A38: Ziekteverzuim | B38: 18887 | C38: =IF(ISNA(VLOOKUP(B38,chauffeurslijst!A:B,2,0)),"",(VLOOKUP(B38,chauffeurslijst!A:B,2,0))) -> Nys Kristof | D38: 42201 | G38: =YEAR(D38) -> 2015
A39: Ziekteverzuim | B39: 19251 | C39: =IF(ISNA(VLOOKUP(B39,chauffeurslijst!A:B,2,0)),"",(VLOOKUP(B39,chauffeurslijst!A:B,2,0))) -> Vanooteghem Johnny | D39: 42242 | E39: SW | G39: =YEAR(D39) -> 2015
A40: Ziekteverzuim | B40: 29075 | C40: =IF(ISNA(VLOOKUP(B40,chauffeurslijst!A:B,2,0)),"",(VLOOKUP(B40,chauffeurslijst!A:B,2,0))) -> Ahmad Herish | D40: 42242 | E40: SW | G40: =YEAR(D40) -> 2015
...
